[2020-01-14 08:46:45][log.py][line:58][INFO] 
[2020-01-14 08:46:45][log.py][line:58][INFO] 脚本开始------------------------------------------------------------------
[2020-01-14 08:46:49][log.py][line:58][INFO] 发送账号【pcxmd3459aa@126.com】正在发送
[2020-01-14 08:46:49][log.py][line:58][INFO] 接受序号【1】【15861597@qq.com】发送成功
[2020-01-14 08:46:49][log.py][line:58][INFO] 
[2020-01-14 08:49:20][log.py][line:68][ERROR] 产生错误于：【kgmir9@163.com】发送失败
[2020-01-14 08:49:20][log.py][line:68][ERROR] (550, b'User has no permission')
[2020-01-14 08:49:20][log.py][line:58][INFO] 
[2020-01-14 08:49:22][log.py][line:68][ERROR] 产生错误于：【 afdfs7892io@126.com】发送失败
[2020-01-14 08:49:22][log.py][line:68][ERROR] (535, b'Error: authentication failed')
[2020-01-14 08:49:22][log.py][line:58][INFO] 
[2020-01-14 08:49:23][log.py][line:68][ERROR] 产生错误于：【sufstq@163.com】发送失败
[2020-01-14 08:49:23][log.py][line:68][ERROR] (535, b'Error: authentication failed')
[2020-01-14 08:49:23][log.py][line:58][INFO] 
[2020-01-14 08:49:24][log.py][line:68][ERROR] 产生错误于：【 zprut3732zt@126.com】发送失败
[2020-01-14 08:49:24][log.py][line:68][ERROR] (535, b'Error: authentication failed')
[2020-01-14 08:49:24][log.py][line:58][INFO] 
[2020-01-14 08:49:26][log.py][line:68][ERROR] 产生错误于：【 kkzcc9457ss@126.com】发送失败
[2020-01-14 08:49:26][log.py][line:68][ERROR] (535, b'Error: authentication failed')
[2020-01-14 08:49:26][log.py][line:58][INFO] 
[2020-01-14 08:49:28][log.py][line:58][INFO] 发送账号【zs059f@163.com】正在发送
[2020-01-14 08:49:28][log.py][line:58][INFO] 接受序号【2】【43895291@qq.com】发送成功
[2020-01-14 08:49:28][log.py][line:58][INFO] 
[2020-01-14 08:51:59][log.py][line:58][INFO] 发送账号【ss13126325@sina.com】正在发送
[2020-01-14 08:51:59][log.py][line:58][INFO] 接受序号【3】【51000973@qq.com】发送成功
[2020-01-14 08:51:59][log.py][line:58][INFO] 
[2020-01-14 08:54:31][log.py][line:68][ERROR] 产生错误于：【fyu452@163.com】发送失败
[2020-01-14 08:54:31][log.py][line:68][ERROR] (550, b'User has no permission')
[2020-01-14 08:54:31][log.py][line:58][INFO] 
[2020-01-14 08:54:32][log.py][line:58][INFO] 发送账号【o2d66l@163.com】正在发送
[2020-01-14 08:54:32][log.py][line:58][INFO] 接受序号【4】【05769743@qq.com】发送成功
[2020-01-14 08:54:32][log.py][line:58][INFO] 
[2020-01-14 08:57:05][log.py][line:58][INFO] 发送账号【hnmoz3439hc@126.com】正在发送
[2020-01-14 08:57:05][log.py][line:58][INFO] 接受序号【5】【77792297@qq.com】发送成功
[2020-01-14 08:57:05][log.py][line:58][INFO] 
[2020-01-14 08:59:36][log.py][line:58][INFO] 发送账号【ywfc20181@126.com】正在发送
[2020-01-14 08:59:36][log.py][line:58][INFO] 接受序号【6】【52927391@qq.com】发送成功
[2020-01-14 08:59:36][log.py][line:58][INFO] 
[2020-01-14 09:02:09][log.py][line:68][ERROR] 产生错误于：【qjr862@163.com】发送失败
[2020-01-14 09:02:09][log.py][line:68][ERROR] (550, b'User has no permission')
[2020-01-14 09:02:09][log.py][line:58][INFO] 
[2020-01-14 09:02:11][log.py][line:58][INFO] 发送账号【ss13126325@sina.com】正在发送
[2020-01-14 09:02:11][log.py][line:58][INFO] 接受序号【7】【33467543@qq.com】发送成功
[2020-01-14 09:02:11][log.py][line:58][INFO] 
[2020-01-14 09:04:44][log.py][line:58][INFO] 发送账号【gfs0ej@163.com】正在发送
[2020-01-14 09:04:44][log.py][line:58][INFO] 接受序号【8】【36415118@qq.com】发送成功
[2020-01-14 09:04:44][log.py][line:58][INFO] 
[2020-01-14 09:07:19][log.py][line:58][INFO] 发送账号【ss13126325@sina.com】正在发送
[2020-01-14 09:07:19][log.py][line:58][INFO] 接受序号【9】【64209284@qq.com】发送成功
[2020-01-14 09:07:19][log.py][line:58][INFO] 
[2020-01-14 09:09:52][log.py][line:58][INFO] 发送账号【wcqta7018af@126.com】正在发送
[2020-01-14 09:09:52][log.py][line:58][INFO] 接受序号【10】【41426825@qq.com】发送成功
[2020-01-14 09:09:52][log.py][line:58][INFO] 
[2020-01-14 09:12:24][log.py][line:58][INFO] 发送账号【oey337@163.com】正在发送
[2020-01-14 09:12:24][log.py][line:58][INFO] 接受序号【11】【30230831@qq.com】发送成功
[2020-01-14 09:12:24][log.py][line:58][INFO] 
[2020-01-14 09:14:56][log.py][line:58][INFO] 发送账号【ss13126325@sina.com】正在发送
[2020-01-14 09:14:56][log.py][line:58][INFO] 接受序号【12】【21650296@qq.com】发送成功
[2020-01-14 09:14:56][log.py][line:58][INFO] 
[2020-01-14 09:17:28][log.py][line:68][ERROR] 产生错误于：【txn956@163.com】发送失败
[2020-01-14 09:17:28][log.py][line:68][ERROR] (550, b'User has no permission')
[2020-01-14 09:17:28][log.py][line:58][INFO] 
[2020-01-14 09:17:29][log.py][line:58][INFO] 发送账号【ow44288040@126.com】正在发送
[2020-01-14 09:17:29][log.py][line:58][INFO] 接受序号【13】【76821492@qq.com】发送成功
[2020-01-14 09:17:29][log.py][line:58][INFO] 
[2020-01-14 09:20:01][log.py][line:58][INFO] 发送账号【ss13126325@sina.com】正在发送
[2020-01-14 09:20:01][log.py][line:58][INFO] 接受序号【14】【61619140@qq.com】发送成功
[2020-01-14 09:20:01][log.py][line:58][INFO] 
[2020-01-14 09:22:33][log.py][line:58][INFO] 发送账号【i5q7jp@163.com】正在发送
[2020-01-14 09:22:33][log.py][line:58][INFO] 接受序号【15】【95697763@qq.com】发送成功
[2020-01-14 09:22:33][log.py][line:58][INFO] 
[2020-01-14 09:25:05][log.py][line:58][INFO] 发送账号【ss13126325@sina.com】正在发送
[2020-01-14 09:25:05][log.py][line:58][INFO] 接受序号【16】【79393078@qq.com】发送成功
[2020-01-14 09:25:05][log.py][line:58][INFO] 
[2020-01-14 09:27:37][log.py][line:58][INFO] 发送账号【ss13126325@sina.com】正在发送
[2020-01-14 09:27:37][log.py][line:58][INFO] 接受序号【17】【58101998@qq.com】发送成功
[2020-01-14 09:27:37][log.py][line:58][INFO] 
[2020-01-14 09:30:09][log.py][line:58][INFO] 发送账号【ss13126325@sina.com】正在发送
[2020-01-14 09:30:09][log.py][line:58][INFO] 接受序号【18】【75828721@qq.com】发送成功
[2020-01-14 09:30:09][log.py][line:58][INFO] 
[2020-01-14 09:32:40][log.py][line:68][ERROR] 产生错误于：【bkt980@163.com】发送失败
[2020-01-14 09:32:40][log.py][line:68][ERROR] (550, b'User has no permission')
[2020-01-14 09:32:40][log.py][line:58][INFO] 
[2020-01-14 09:32:41][log.py][line:68][ERROR] 产生错误于：【ao06q0@163.com】发送失败
[2020-01-14 09:32:41][log.py][line:68][ERROR] (535, b'Error: authentication failed')
[2020-01-14 09:32:41][log.py][line:58][INFO] 
[2020-01-14 09:32:43][log.py][line:68][ERROR] 产生错误于：【hem355@163.com】发送失败
[2020-01-14 09:32:43][log.py][line:68][ERROR] (550, b'User has no permission')
[2020-01-14 09:32:43][log.py][line:58][INFO] 
[2020-01-14 09:32:45][log.py][line:58][INFO] 发送账号【ss13126325@sina.com】正在发送
[2020-01-14 09:32:45][log.py][line:58][INFO] 接受序号【19】【52044732@qq.com】发送成功
[2020-01-14 09:32:45][log.py][line:58][INFO] 
[2020-01-14 09:35:16][log.py][line:68][ERROR] 产生错误于：【fql659@163.com】发送失败
[2020-01-14 09:35:16][log.py][line:68][ERROR] (550, b'User has no permission')
[2020-01-14 09:35:16][log.py][line:58][INFO] 
[2020-01-14 09:35:19][log.py][line:58][INFO] 发送账号【dv93379053@126.com】正在发送
[2020-01-14 09:35:19][log.py][line:58][INFO] 接受序号【20】【76847346@qq.com】发送成功
[2020-01-14 09:35:19][log.py][line:58][INFO] 
[2020-01-14 09:37:50][log.py][line:68][ERROR] 产生错误于：【kkh175@163.com】发送失败
[2020-01-14 09:37:50][log.py][line:68][ERROR] (550, b'User has no permission')
[2020-01-14 09:37:50][log.py][line:58][INFO] 
[2020-01-14 09:37:52][log.py][line:68][ERROR] 产生错误于：【vjz463@163.com】发送失败
[2020-01-14 09:37:52][log.py][line:68][ERROR] (550, b'User has no permission')
[2020-01-14 09:37:52][log.py][line:58][INFO] 
[2020-01-14 09:37:53][log.py][line:58][INFO] 发送账号【ss13126325@sina.com】正在发送
[2020-01-14 09:37:53][log.py][line:58][INFO] 接受序号【21】【84479809@qq.com】发送成功
[2020-01-14 09:37:53][log.py][line:58][INFO] 
[2020-01-14 09:40:25][log.py][line:68][ERROR] 产生错误于：【msq781@163.com】发送失败
[2020-01-14 09:40:25][log.py][line:68][ERROR] (550, b'User has no permission')
[2020-01-14 09:40:25][log.py][line:58][INFO] 
[2020-01-14 09:40:26][log.py][line:68][ERROR] 产生错误于：【 exado5238vw@126.com】发送失败
[2020-01-14 09:40:26][log.py][line:68][ERROR] (535, b'Error: authentication failed')
[2020-01-14 09:40:26][log.py][line:58][INFO] 
[2020-01-14 09:40:27][log.py][line:68][ERROR] 产生错误于：【yas785@163.com】发送失败
[2020-01-14 09:40:27][log.py][line:68][ERROR] (550, b'User has no permission')
[2020-01-14 09:40:27][log.py][line:58][INFO] 
[2020-01-14 09:40:29][log.py][line:58][INFO] 发送账号【akyrt8474uf@126.com】正在发送
[2020-01-14 09:40:29][log.py][line:58][INFO] 接受序号【22】【22993994@qq.com】发送成功
[2020-01-14 09:40:29][log.py][line:58][INFO] 
[2020-01-14 09:43:01][log.py][line:58][INFO] 发送账号【i8y6y4@163.com】正在发送
[2020-01-14 09:43:01][log.py][line:58][INFO] 接受序号【23】【44360436@qq.com】发送成功
[2020-01-14 09:43:01][log.py][line:58][INFO] 
[2020-01-14 09:45:32][log.py][line:68][ERROR] 产生错误于：【ja70EZ@163.com】发送失败
[2020-01-14 09:45:32][log.py][line:68][ERROR] (550, b'User has no permission')
[2020-01-14 09:45:32][log.py][line:58][INFO] 
[2020-01-14 09:45:34][log.py][line:58][INFO] 发送账号【oawyv6890wz@126.com】正在发送
[2020-01-14 09:45:34][log.py][line:58][INFO] 接受序号【24】【55082132@qq.com】发送成功
[2020-01-14 09:45:34][log.py][line:58][INFO] 
[2020-01-14 09:48:06][log.py][line:58][INFO] 发送账号【ss13126325@sina.com】正在发送
[2020-01-14 09:48:06][log.py][line:58][INFO] 接受序号【25】【35552197@qq.com】发送成功
[2020-01-14 09:48:06][log.py][line:58][INFO] 
[2020-01-14 09:50:38][log.py][line:58][INFO] 发送账号【ss13126325@sina.com】正在发送
[2020-01-14 09:50:38][log.py][line:58][INFO] 接受序号【26】【14788243@qq.com】发送成功
[2020-01-14 09:50:38][log.py][line:58][INFO] 
[2020-01-14 09:53:10][log.py][line:58][INFO] 发送账号【w7t7wa@163.com】正在发送
[2020-01-14 09:53:10][log.py][line:58][INFO] 接受序号【27】【34153109@qq.com】发送成功
[2020-01-14 09:53:10][log.py][line:58][INFO] 
[2020-01-14 09:55:41][log.py][line:68][ERROR] 产生错误于：【cka382@163.com】发送失败
[2020-01-14 09:55:41][log.py][line:68][ERROR] (550, b'User has no permission')
[2020-01-14 09:55:41][log.py][line:58][INFO] 
[2020-01-14 09:55:42][log.py][line:68][ERROR] 产生错误于：【bwb721@163.com】发送失败
[2020-01-14 09:55:42][log.py][line:68][ERROR] (550, b'User has no permission')
[2020-01-14 09:55:42][log.py][line:58][INFO] 
[2020-01-14 09:55:44][log.py][line:68][ERROR] 产生错误于：【vev591@163.com】发送失败
[2020-01-14 09:55:44][log.py][line:68][ERROR] (550, b'User has no permission')
[2020-01-14 09:55:44][log.py][line:58][INFO] 
[2020-01-14 09:55:45][log.py][line:58][INFO] 发送账号【gk491m@163.com】正在发送
[2020-01-14 09:55:45][log.py][line:58][INFO] 接受序号【28】【28597992@qq.com】发送成功
[2020-01-14 09:55:45][log.py][line:58][INFO] 
[2020-01-14 09:58:17][log.py][line:68][ERROR] 产生错误于：【pa73kl@163.com】发送失败
[2020-01-14 09:58:17][log.py][line:68][ERROR] (550, b'User has no permission')
[2020-01-14 09:58:17][log.py][line:58][INFO] 
[2020-01-14 09:58:18][log.py][line:68][ERROR] 产生错误于：【pws791@163.com】发送失败
[2020-01-14 09:58:18][log.py][line:68][ERROR] (550, b'User has no permission')
[2020-01-14 09:58:18][log.py][line:58][INFO] 
[2020-01-14 09:58:20][log.py][line:58][INFO] 发送账号【gfs0ej@163.com】正在发送
[2020-01-14 09:58:20][log.py][line:58][INFO] 接受序号【29】【00254843@qq.com】发送成功
[2020-01-14 09:58:20][log.py][line:58][INFO] 
[2020-01-14 10:00:51][log.py][line:68][ERROR] 产生错误于：【vev591@163.com】发送失败
[2020-01-14 10:00:51][log.py][line:68][ERROR] (550, b'User has no permission')
[2020-01-14 10:00:51][log.py][line:58][INFO] 
[2020-01-14 10:00:53][log.py][line:58][INFO] 发送账号【izt26v@163.com】正在发送
[2020-01-14 10:00:53][log.py][line:58][INFO] 接受序号【30】【11797982@qq.com】发送成功
[2020-01-14 10:00:53][log.py][line:58][INFO] 
[2020-01-14 10:03:25][log.py][line:68][ERROR] 产生错误于：【 rkmym8552vj@126.com】发送失败
[2020-01-14 10:03:25][log.py][line:68][ERROR] (535, b'Error: authentication failed')
[2020-01-14 10:03:25][log.py][line:58][INFO] 
[2020-01-14 10:03:27][log.py][line:68][ERROR] 产生错误于：【nk75h4@163.com】发送失败
[2020-01-14 10:03:27][log.py][line:68][ERROR] (550, b'User has no permission')
[2020-01-14 10:03:27][log.py][line:58][INFO] 
[2020-01-14 10:03:28][log.py][line:58][INFO] 发送账号【oawyv6890wz@126.com】正在发送
[2020-01-14 10:03:28][log.py][line:58][INFO] 接受序号【31】【15865911@qq.com】发送成功
[2020-01-14 10:03:28][log.py][line:58][INFO] 
[2020-01-14 10:05:59][log.py][line:68][ERROR] 产生错误于：【 sjw10q@163.com】发送失败
[2020-01-14 10:05:59][log.py][line:68][ERROR] (535, b'Error: authentication failed')
[2020-01-14 10:05:59][log.py][line:58][INFO] 
[2020-01-14 10:06:01][log.py][line:58][INFO] 发送账号【ss13126325@sina.com】正在发送
[2020-01-14 10:06:01][log.py][line:58][INFO] 接受序号【32】【24792018@qq.com】发送成功
[2020-01-14 10:06:01][log.py][line:58][INFO] 
[2020-01-14 10:08:33][log.py][line:58][INFO] 发送账号【jajhm301py@126.com】正在发送
[2020-01-14 10:08:33][log.py][line:58][INFO] 接受序号【33】【19309026@qq.com】发送成功
[2020-01-14 10:08:33][log.py][line:58][INFO] 
[2020-01-14 10:11:05][log.py][line:58][INFO] 发送账号【u1v00h@163.com】正在发送
[2020-01-14 10:11:05][log.py][line:58][INFO] 接受序号【34】【13196810@qq.com】发送成功
[2020-01-14 10:11:05][log.py][line:58][INFO] 
[2020-01-14 10:13:36][log.py][line:68][ERROR] 产生错误于：【 i6m5nh@163.com】发送失败
[2020-01-14 10:13:36][log.py][line:68][ERROR] (535, b'Error: authentication failed')
[2020-01-14 10:13:36][log.py][line:58][INFO] 
[2020-01-14 10:16:54][log.py][line:68][ERROR] 产生错误于：【umr637@163.com】发送失败
[2020-01-14 10:16:54][log.py][line:68][ERROR] (550, b'User has no permission')
[2020-01-14 10:16:54][log.py][line:58][INFO] 
[2020-01-14 10:16:57][log.py][line:58][INFO] 发送账号【ohlmd5530rh@126.com】正在发送
[2020-01-14 10:16:57][log.py][line:58][INFO] 接受序号【35】【98760703@qq.com】发送成功
[2020-01-14 10:16:57][log.py][line:58][INFO] 
[2020-01-14 10:19:29][log.py][line:68][ERROR] 产生错误于：【awv253@163.com】发送失败
[2020-01-14 10:19:29][log.py][line:68][ERROR] (550, b'User has no permission')
[2020-01-14 10:19:29][log.py][line:58][INFO] 
[2020-01-14 10:19:31][log.py][line:58][INFO] 发送账号【ucr2ue@163.com】正在发送
[2020-01-14 10:19:31][log.py][line:58][INFO] 接受序号【36】【01065015@qq.com】发送成功
[2020-01-14 10:19:31][log.py][line:58][INFO] 
[2020-01-14 10:22:03][log.py][line:58][INFO] 发送账号【nah5ae@163.com】正在发送
[2020-01-14 10:22:03][log.py][line:58][INFO] 接受序号【37】【84065135@qq.com】发送成功
[2020-01-14 10:22:03][log.py][line:58][INFO] 
[2020-01-14 10:24:34][log.py][line:58][INFO] 发送账号【u4s658@163.com】正在发送
[2020-01-14 10:24:34][log.py][line:58][INFO] 接受序号【38】【51518469@qq.com】发送成功
[2020-01-14 10:24:34][log.py][line:58][INFO] 
[2020-01-14 10:27:07][log.py][line:58][INFO] 发送账号【plony1572fn@126.com】正在发送
[2020-01-14 10:27:07][log.py][line:58][INFO] 接受序号【39】【04741935@qq.com】发送成功
[2020-01-14 10:27:07][log.py][line:58][INFO] 
[2020-01-14 10:29:39][log.py][line:68][ERROR] 产生错误于：【tvd387@163.com】发送失败
[2020-01-14 10:29:39][log.py][line:68][ERROR] (550, b'User has no permission')
[2020-01-14 10:29:39][log.py][line:58][INFO] 
[2020-01-14 10:29:40][log.py][line:68][ERROR] 产生错误于：【ewb548@163.com】发送失败
[2020-01-14 10:29:40][log.py][line:68][ERROR] (550, b'User has no permission')
[2020-01-14 10:29:40][log.py][line:58][INFO] 
[2020-01-14 10:29:41][log.py][line:68][ERROR] 产生错误于：【v8eyyn@163.com】发送失败
[2020-01-14 10:29:41][log.py][line:68][ERROR] (550, b'User has no permission')
[2020-01-14 10:29:41][log.py][line:58][INFO] 
[2020-01-14 10:29:43][log.py][line:58][INFO] 发送账号【yxk845@163.com】正在发送
[2020-01-14 10:29:43][log.py][line:58][INFO] 接受序号【40】【35527108@qq.com】发送成功
[2020-01-14 10:29:43][log.py][line:58][INFO] 
[2020-01-14 10:32:14][log.py][line:68][ERROR] 产生错误于：【mkp528@163.com】发送失败
[2020-01-14 10:32:14][log.py][line:68][ERROR] (550, b'User has no permission')
[2020-01-14 10:32:14][log.py][line:58][INFO] 
[2020-01-14 10:32:16][log.py][line:58][INFO] 发送账号【gfs0ej@163.com】正在发送
[2020-01-14 10:32:16][log.py][line:58][INFO] 接受序号【41】【00927380@qq.com】发送成功
[2020-01-14 10:32:16][log.py][line:58][INFO] 
[2020-01-14 10:34:48][log.py][line:68][ERROR] 产生错误于：【jo91888@126.com】发送失败
[2020-01-14 10:34:48][log.py][line:68][ERROR] (550, b'\xd3\xc3\xbb\xa7\xce\xde\xc8\xa8\xb5\xc7\xc2\xbd')
[2020-01-14 10:34:48][log.py][line:58][INFO] 
[2020-01-14 10:34:49][log.py][line:58][INFO] 发送账号【vfqcz3108nx@126.com】正在发送
[2020-01-14 10:34:49][log.py][line:58][INFO] 接受序号【42】【64098609@qq.com】发送成功
[2020-01-14 10:34:49][log.py][line:58][INFO] 
[2020-01-14 10:37:21][log.py][line:58][INFO] 发送账号【ss13126325@sina.com】正在发送
[2020-01-14 10:37:21][log.py][line:58][INFO] 接受序号【43】【21857230@qq.com】发送成功
[2020-01-14 10:37:21][log.py][line:58][INFO] 
[2020-01-14 10:39:53][log.py][line:58][INFO] 发送账号【hes7ks@163.com】正在发送
[2020-01-14 10:39:53][log.py][line:58][INFO] 接受序号【44】【03950065@qq.com】发送成功
[2020-01-14 10:39:53][log.py][line:58][INFO] 
[2020-01-14 10:42:24][log.py][line:58][INFO] 发送账号【ss13126325@sina.com】正在发送
[2020-01-14 10:42:24][log.py][line:58][INFO] 接受序号【45】【97718119@qq.com】发送成功
[2020-01-14 10:42:24][log.py][line:58][INFO] 
[2020-01-14 10:44:57][log.py][line:58][INFO] 发送账号【zhgrp3927ek@126.com】正在发送
[2020-01-14 10:44:57][log.py][line:58][INFO] 接受序号【46】【39570188@qq.com】发送成功
[2020-01-14 10:44:57][log.py][line:58][INFO] 
[2020-01-14 10:47:28][log.py][line:68][ERROR] 产生错误于：【mli413@163.com】发送失败
[2020-01-14 10:47:28][log.py][line:68][ERROR] (550, b'User has no permission')
[2020-01-14 10:47:28][log.py][line:58][INFO] 
[2020-01-14 10:47:30][log.py][line:58][INFO] 发送账号【ss13126325@sina.com】正在发送
[2020-01-14 10:47:30][log.py][line:58][INFO] 接受序号【47】【16114191@qq.com】发送成功
[2020-01-14 10:47:30][log.py][line:58][INFO] 
[2020-01-14 10:50:02][log.py][line:58][INFO] 发送账号【qcoou283gy@126.com】正在发送
[2020-01-14 10:50:02][log.py][line:58][INFO] 接受序号【48】【86428376@qq.com】发送成功
[2020-01-14 10:50:02][log.py][line:58][INFO] 
[2020-01-14 10:52:33][log.py][line:58][INFO] 发送账号【n4681f@163.com】正在发送
[2020-01-14 10:52:33][log.py][line:58][INFO] 接受序号【49】【37394538@qq.com】发送成功
[2020-01-14 10:52:33][log.py][line:58][INFO] 
[2020-01-14 10:55:05][log.py][line:58][INFO] 发送账号【ss13126325@sina.com】正在发送
[2020-01-14 10:55:05][log.py][line:58][INFO] 接受序号【50】【05940318@qq.com】发送成功
[2020-01-14 10:55:05][log.py][line:58][INFO] 
[2020-01-14 10:57:37][log.py][line:68][ERROR] 产生错误于：【xau247@163.com】发送失败
[2020-01-14 10:57:37][log.py][line:68][ERROR] (550, b'User has no permission')
[2020-01-14 10:57:37][log.py][line:58][INFO] 
[2020-01-14 10:57:39][log.py][line:68][ERROR] 产生错误于：【 yjdvv5943hb@126.com】发送失败
[2020-01-14 10:57:39][log.py][line:68][ERROR] (535, b'Error: authentication failed')
[2020-01-14 10:57:39][log.py][line:58][INFO] 
[2020-01-14 10:57:42][log.py][line:58][INFO] 发送账号【d706a3@163.com】正在发送
[2020-01-14 10:57:42][log.py][line:58][INFO] 接受序号【51】【04065464@qq.com】发送成功
[2020-01-14 10:57:42][log.py][line:58][INFO] 
[2020-01-14 11:00:13][log.py][line:68][ERROR] 产生错误于：【h9280p@163.com】发送失败
[2020-01-14 11:00:13][log.py][line:68][ERROR] (535, b'Error: authentication failed')
[2020-01-14 11:00:13][log.py][line:58][INFO] 
[2020-01-14 11:00:14][log.py][line:58][INFO] 发送账号【ss13126325@sina.com】正在发送
[2020-01-14 11:00:14][log.py][line:58][INFO] 接受序号【52】【76610685@qq.com】发送成功
[2020-01-14 11:00:14][log.py][line:58][INFO] 
[2020-01-14 11:02:46][log.py][line:58][INFO] 发送账号【zgnk71219@126.com】正在发送
[2020-01-14 11:02:46][log.py][line:58][INFO] 接受序号【53】【88834357@qq.com】发送成功
[2020-01-14 11:02:46][log.py][line:58][INFO] 
[2020-01-14 11:05:18][log.py][line:58][INFO] 发送账号【xxrso4755qg@126.com】正在发送
[2020-01-14 11:05:18][log.py][line:58][INFO] 接受序号【54】【89880710@qq.com】发送成功
[2020-01-14 11:05:18][log.py][line:58][INFO] 
[2020-01-14 11:07:51][log.py][line:58][INFO] 发送账号【ntqct3132ty@126.com】正在发送
[2020-01-14 11:07:51][log.py][line:58][INFO] 接受序号【55】【69988485@qq.com】发送成功
[2020-01-14 11:07:51][log.py][line:58][INFO] 
[2020-01-14 11:10:23][log.py][line:58][INFO] 发送账号【ss13126325@sina.com】正在发送
[2020-01-14 11:10:23][log.py][line:58][INFO] 接受序号【56】【38930702@qq.com】发送成功
[2020-01-14 11:10:23][log.py][line:58][INFO] 
[2020-01-14 11:12:54][log.py][line:58][INFO] 发送账号【boeie5075ey@126.com】正在发送
[2020-01-14 11:12:54][log.py][line:58][INFO] 接受序号【57】【72774433@qq.com】发送成功
[2020-01-14 11:12:54][log.py][line:58][INFO] 
[2020-01-14 11:15:26][log.py][line:68][ERROR] 产生错误于：【bkt980@163.com】发送失败
[2020-01-14 11:15:26][log.py][line:68][ERROR] (550, b'User has no permission')
[2020-01-14 11:15:26][log.py][line:58][INFO] 
[2020-01-14 11:15:28][log.py][line:58][INFO] 发送账号【cwgdk3565rs@126.com】正在发送
[2020-01-14 11:15:28][log.py][line:58][INFO] 接受序号【58】【19267626@qq.com】发送成功
[2020-01-14 11:15:28][log.py][line:58][INFO] 
[2020-01-14 11:18:00][log.py][line:68][ERROR] 产生错误于：【ex9p0q@163.com】发送失败
[2020-01-14 11:18:00][log.py][line:68][ERROR] (550, b'User has no permission')
[2020-01-14 11:18:00][log.py][line:58][INFO] 
[2020-01-14 11:18:02][log.py][line:58][INFO] 发送账号【zrpoz1516lc@126.com】正在发送
[2020-01-14 11:18:02][log.py][line:58][INFO] 接受序号【59】【27905638@qq.com】发送成功
[2020-01-14 11:18:02][log.py][line:58][INFO] 
[2020-01-14 11:20:34][log.py][line:68][ERROR] 产生错误于：【gwlhxo@163.com】发送失败
[2020-01-14 11:20:34][log.py][line:68][ERROR] (550, b'User has no permission')
[2020-01-14 11:20:34][log.py][line:58][INFO] 
[2020-01-14 11:20:37][log.py][line:58][INFO] 发送账号【ss13126325@sina.com】正在发送
[2020-01-14 11:20:37][log.py][line:58][INFO] 接受序号【60】【53497465@qq.com】发送成功
[2020-01-14 11:20:37][log.py][line:58][INFO] 
[2020-01-14 11:23:09][log.py][line:68][ERROR] 产生错误于：【d980f1@163.com】发送失败
[2020-01-14 11:23:09][log.py][line:68][ERROR] (535, b'Error: authentication failed')
[2020-01-14 11:23:09][log.py][line:58][INFO] 
[2020-01-14 11:23:11][log.py][line:68][ERROR] 产生错误于：【ht8cxf@163.com】发送失败
[2020-01-14 11:23:11][log.py][line:68][ERROR] (550, b'User has no permission')
[2020-01-14 11:23:11][log.py][line:58][INFO] 
[2020-01-14 11:23:13][log.py][line:68][ERROR] 产生错误于：【xuq208@163.com】发送失败
[2020-01-14 11:23:13][log.py][line:68][ERROR] (550, b'User has no permission')
[2020-01-14 11:23:13][log.py][line:58][INFO] 
[2020-01-14 11:23:16][log.py][line:58][INFO] 发送账号【ss13126325@sina.com】正在发送
[2020-01-14 11:23:16][log.py][line:58][INFO] 接受序号【61】【26692581@qq.com】发送成功
[2020-01-14 11:23:16][log.py][line:58][INFO] 
[2020-01-14 11:25:47][log.py][line:58][INFO] 发送账号【ss13126325@sina.com】正在发送
[2020-01-14 11:25:47][log.py][line:58][INFO] 接受序号【62】【78846638@qq.com】发送成功
[2020-01-14 11:25:47][log.py][line:58][INFO] 
[2020-01-14 11:28:20][log.py][line:58][INFO] 发送账号【ss13126325@sina.com】正在发送
[2020-01-14 11:28:20][log.py][line:58][INFO] 接受序号【63】【94579505@qq.com】发送成功
[2020-01-14 11:28:20][log.py][line:58][INFO] 
[2020-01-14 11:30:51][log.py][line:68][ERROR] 产生错误于：【lwt544@163.com】发送失败
[2020-01-14 11:30:51][log.py][line:68][ERROR] (550, b'User has no permission')
[2020-01-14 11:30:51][log.py][line:58][INFO] 
[2020-01-14 11:30:52][log.py][line:58][INFO] 发送账号【ss13126325@sina.com】正在发送
[2020-01-14 11:30:52][log.py][line:58][INFO] 接受序号【64】【05727021@qq.com】发送成功
[2020-01-14 11:30:52][log.py][line:58][INFO] 
[2020-01-14 11:33:24][log.py][line:58][INFO] 发送账号【dr563p@163.com】正在发送
[2020-01-14 11:33:24][log.py][line:58][INFO] 接受序号【65】【84997971@qq.com】发送成功
[2020-01-14 11:33:24][log.py][line:58][INFO] 
[2020-01-14 11:35:56][log.py][line:68][ERROR] 产生错误于：【bph824@163.com】发送失败
[2020-01-14 11:35:56][log.py][line:68][ERROR] (550, b'User has no permission')
[2020-01-14 11:35:56][log.py][line:58][INFO] 
[2020-01-14 11:35:58][log.py][line:58][INFO] 发送账号【ss13126325@sina.com】正在发送
[2020-01-14 11:35:58][log.py][line:58][INFO] 接受序号【66】【52413473@qq.com】发送成功
[2020-01-14 11:35:58][log.py][line:58][INFO] 
[2020-01-14 11:38:30][log.py][line:68][ERROR] 产生错误于：【fze929@163.com】发送失败
[2020-01-14 11:38:30][log.py][line:68][ERROR] (550, b'User has no permission')
[2020-01-14 11:38:30][log.py][line:58][INFO] 
[2020-01-14 11:38:31][log.py][line:68][ERROR] 产生错误于：【vjh695@163.com】发送失败
[2020-01-14 11:38:31][log.py][line:68][ERROR] (550, b'User has no permission')
[2020-01-14 11:38:31][log.py][line:58][INFO] 
[2020-01-14 11:38:33][log.py][line:58][INFO] 发送账号【ss13126325@sina.com】正在发送
[2020-01-14 11:38:33][log.py][line:58][INFO] 接受序号【67】【76530542@qq.com】发送成功
[2020-01-14 11:38:33][log.py][line:58][INFO] 
[2020-01-14 11:41:05][log.py][line:68][ERROR] 产生错误于：【xbu966@163.com】发送失败
[2020-01-14 11:41:05][log.py][line:68][ERROR] (550, b'User has no permission')
[2020-01-14 11:41:05][log.py][line:58][INFO] 
[2020-01-14 11:41:08][log.py][line:68][ERROR] 产生错误于：【 bivzq3211jw@126.com】发送失败
[2020-01-14 11:41:08][log.py][line:68][ERROR] (535, b'Error: authentication failed')
[2020-01-14 11:41:08][log.py][line:58][INFO] 
[2020-01-14 11:41:10][log.py][line:58][INFO] 发送账号【cd77rq@163.com】正在发送
[2020-01-14 11:41:10][log.py][line:58][INFO] 接受序号【68】【69242963@qq.com】发送成功
[2020-01-14 11:41:10][log.py][line:58][INFO] 
[2020-01-14 11:43:42][log.py][line:58][INFO] 发送账号【bismw8916cu@126.com】正在发送
[2020-01-14 11:43:42][log.py][line:58][INFO] 接受序号【69】【81234046@qq.com】发送成功
[2020-01-14 11:43:42][log.py][line:58][INFO] 
[2020-01-14 11:46:13][log.py][line:58][INFO] 发送账号【mdzxe1907rg@126.com】正在发送
[2020-01-14 11:46:13][log.py][line:58][INFO] 接受序号【70】【58332704@qq.com】发送成功
[2020-01-14 11:46:13][log.py][line:58][INFO] 
[2020-01-14 11:48:45][log.py][line:58][INFO] 发送账号【xhpky2744ej@126.com】正在发送
[2020-01-14 11:48:45][log.py][line:58][INFO] 接受序号【71】【91443800@qq.com】发送成功
[2020-01-14 11:48:45][log.py][line:58][INFO] 
[2020-01-14 11:51:17][log.py][line:58][INFO] 发送账号【ss13126325@sina.com】正在发送
[2020-01-14 11:51:17][log.py][line:58][INFO] 接受序号【72】【96228985@qq.com】发送成功
[2020-01-14 11:51:17][log.py][line:58][INFO] 
[2020-01-14 11:53:56][log.py][line:58][INFO] 发送账号【xkq9kr@163.com】正在发送
[2020-01-14 11:53:56][log.py][line:58][INFO] 接受序号【73】【62327693@qq.com】发送成功
[2020-01-14 11:53:56][log.py][line:58][INFO] 
[2020-01-14 11:56:29][log.py][line:58][INFO] 发送账号【qcoou283gy@126.com】正在发送
[2020-01-14 11:56:29][log.py][line:58][INFO] 接受序号【74】【21384106@qq.com】发送成功
[2020-01-14 11:56:29][log.py][line:58][INFO] 
[2020-01-14 11:59:09][log.py][line:58][INFO] 发送账号【b142qs@163.com】正在发送
[2020-01-14 11:59:09][log.py][line:58][INFO] 接受序号【75】【87120021@qq.com】发送成功
[2020-01-14 11:59:09][log.py][line:58][INFO] 
[2020-01-14 12:01:49][log.py][line:58][INFO] 发送账号【urt6ca@163.com】正在发送
[2020-01-14 12:01:49][log.py][line:58][INFO] 接受序号【76】【71287628@qq.com】发送成功
[2020-01-14 12:01:49][log.py][line:58][INFO] 
[2020-01-14 12:04:21][log.py][line:58][INFO] 发送账号【lthyr8046di@126.com】正在发送
[2020-01-14 12:04:21][log.py][line:58][INFO] 接受序号【77】【08907830@qq.com】发送成功
[2020-01-14 12:04:21][log.py][line:58][INFO] 
[2020-01-14 12:06:53][log.py][line:58][INFO] 发送账号【jrkbr885qb@126.com】正在发送
[2020-01-14 12:06:53][log.py][line:58][INFO] 接受序号【78】【41608015@qq.com】发送成功
[2020-01-14 12:06:53][log.py][line:58][INFO] 
[2020-01-14 12:09:26][log.py][line:58][INFO] 发送账号【pf279o@163.com】正在发送
[2020-01-14 12:09:26][log.py][line:58][INFO] 接受序号【79】【56192897@qq.com】发送成功
[2020-01-14 12:09:26][log.py][line:58][INFO] 
[2020-01-14 12:11:57][log.py][line:58][INFO] 发送账号【dquan242sl@126.com】正在发送
[2020-01-14 12:11:57][log.py][line:58][INFO] 接受序号【80】【85640501@qq.com】发送成功
[2020-01-14 12:11:57][log.py][line:58][INFO] 
[2020-01-14 12:14:29][log.py][line:58][INFO] 发送账号【ss13126325@sina.com】正在发送
[2020-01-14 12:14:29][log.py][line:58][INFO] 接受序号【81】【88102225@qq.com】发送成功
[2020-01-14 12:14:29][log.py][line:58][INFO] 
[2020-01-14 12:17:01][log.py][line:68][ERROR] 产生错误于：【mwz710@163.com】发送失败
[2020-01-14 12:17:01][log.py][line:68][ERROR] (550, b'User has no permission')
[2020-01-14 12:17:01][log.py][line:58][INFO] 
[2020-01-14 12:17:03][log.py][line:68][ERROR] 产生错误于：【 afdfs7892io@126.com】发送失败
[2020-01-14 12:17:03][log.py][line:68][ERROR] (535, b'Error: authentication failed')
[2020-01-14 12:17:03][log.py][line:58][INFO] 
[2020-01-14 12:17:05][log.py][line:58][INFO] 发送账号【h6x088@163.com】正在发送
[2020-01-14 12:17:05][log.py][line:58][INFO] 接受序号【82】【10702223@qq.com】发送成功
[2020-01-14 12:17:05][log.py][line:58][INFO] 
[2020-01-14 12:19:36][log.py][line:58][INFO] 发送账号【x2979j@163.com】正在发送
[2020-01-14 12:19:36][log.py][line:58][INFO] 接受序号【83】【41530679@qq.com】发送成功
[2020-01-14 12:19:36][log.py][line:58][INFO] 
[2020-01-14 12:22:08][log.py][line:58][INFO] 发送账号【ss13126325@sina.com】正在发送
[2020-01-14 12:22:08][log.py][line:58][INFO] 接受序号【84】【07715759@qq.com】发送成功
[2020-01-14 12:22:08][log.py][line:58][INFO] 
[2020-01-14 12:24:39][log.py][line:68][ERROR] 产生错误于：【scf635@163.com】发送失败
[2020-01-14 12:24:39][log.py][line:68][ERROR] (550, b'User has no permission')
[2020-01-14 12:24:39][log.py][line:58][INFO] 
[2020-01-14 12:24:41][log.py][line:58][INFO] 发送账号【qlfnb3718ii@126.com】正在发送
[2020-01-14 12:24:41][log.py][line:58][INFO] 接受序号【85】【16734163@qq.com】发送成功
[2020-01-14 12:24:41][log.py][line:58][INFO] 
[2020-01-14 12:27:12][log.py][line:68][ERROR] 产生错误于：【zee475@163.com】发送失败
[2020-01-14 12:27:12][log.py][line:68][ERROR] (550, b'User has no permission')
[2020-01-14 12:27:12][log.py][line:58][INFO] 
[2020-01-14 12:27:13][log.py][line:68][ERROR] 产生错误于：【zpa781@163.com】发送失败
[2020-01-14 12:27:13][log.py][line:68][ERROR] (550, b'User has no permission')
[2020-01-14 12:27:13][log.py][line:58][INFO] 
[2020-01-14 12:27:15][log.py][line:58][INFO] 发送账号【kbu1dc@163.com】正在发送
[2020-01-14 12:27:15][log.py][line:58][INFO] 接受序号【86】【93131536@qq.com】发送成功
[2020-01-14 12:27:15][log.py][line:58][INFO] 
[2020-01-14 12:29:47][log.py][line:58][INFO] 发送账号【j9q7g4@163.com】正在发送
[2020-01-14 12:29:47][log.py][line:58][INFO] 接受序号【87】【17732994@qq.com】发送成功
[2020-01-14 12:29:47][log.py][line:58][INFO] 
[2020-01-14 12:32:19][log.py][line:58][INFO] 发送账号【mhujp1224ir@126.com】正在发送
[2020-01-14 12:32:19][log.py][line:58][INFO] 接受序号【88】【79035699@qq.com】发送成功
[2020-01-14 12:32:19][log.py][line:58][INFO] 
[2020-01-14 12:34:51][log.py][line:58][INFO] 发送账号【ocern5508pf@126.com】正在发送
[2020-01-14 12:34:51][log.py][line:58][INFO] 接受序号【89】【20692104@qq.com】发送成功
[2020-01-14 12:34:51][log.py][line:58][INFO] 
[2020-01-14 12:37:22][log.py][line:68][ERROR] 产生错误于：【sef618@163.com】发送失败
[2020-01-14 12:37:22][log.py][line:68][ERROR] (550, b'User has no permission')
[2020-01-14 12:37:22][log.py][line:58][INFO] 
[2020-01-14 12:37:24][log.py][line:58][INFO] 发送账号【ss13126325@sina.com】正在发送
[2020-01-14 12:37:24][log.py][line:58][INFO] 接受序号【90】【62558589@qq.com】发送成功
[2020-01-14 12:37:24][log.py][line:58][INFO] 
[2020-01-14 12:39:57][log.py][line:58][INFO] 发送账号【kc84jt@163.com】正在发送
[2020-01-14 12:39:57][log.py][line:58][INFO] 接受序号【91】【93704183@qq.com】发送成功
[2020-01-14 12:39:57][log.py][line:58][INFO] 
[2020-01-14 12:42:29][log.py][line:68][ERROR] 产生错误于：【dos297@163.com】发送失败
[2020-01-14 12:42:29][log.py][line:68][ERROR] (550, b'User has no permission')
[2020-01-14 12:42:29][log.py][line:58][INFO] 
[2020-01-14 12:42:31][log.py][line:58][INFO] 发送账号【ss13126325@sina.com】正在发送
[2020-01-14 12:42:31][log.py][line:58][INFO] 接受序号【92】【61735242@qq.com】发送成功
[2020-01-14 12:42:31][log.py][line:58][INFO] 
[2020-01-14 12:45:18][log.py][line:58][INFO] 发送账号【ss13126325@sina.com】正在发送
[2020-01-14 12:45:18][log.py][line:58][INFO] 接受序号【93】【71062850@qq.com】发送成功
[2020-01-14 12:45:18][log.py][line:58][INFO] 
[2020-01-14 12:47:50][log.py][line:68][ERROR] 产生错误于：【cudm0r@163.com】发送失败
[2020-01-14 12:47:50][log.py][line:68][ERROR] (550, b'User has no permission')
[2020-01-14 12:47:50][log.py][line:58][INFO] 
[2020-01-14 12:47:53][log.py][line:58][INFO] 发送账号【wybfd0016op@126.com】正在发送
[2020-01-14 12:47:53][log.py][line:58][INFO] 接受序号【94】【28554743@qq.com】发送成功
[2020-01-14 12:47:53][log.py][line:58][INFO] 
[2020-01-14 12:50:26][log.py][line:58][INFO] 发送账号【oe495r@163.com】正在发送
[2020-01-14 12:50:26][log.py][line:58][INFO] 接受序号【95】【21783737@qq.com】发送成功
[2020-01-14 12:50:26][log.py][line:58][INFO] 
[2020-01-14 12:52:58][log.py][line:68][ERROR] 产生错误于：【yqb873@163.com】发送失败
[2020-01-14 12:52:58][log.py][line:68][ERROR] (550, b'User has no permission')
[2020-01-14 12:52:58][log.py][line:58][INFO] 
[2020-01-14 12:52:59][log.py][line:68][ERROR] 产生错误于：【pee274@163.com】发送失败
[2020-01-14 12:52:59][log.py][line:68][ERROR] (550, b'User has no permission')
[2020-01-14 12:52:59][log.py][line:58][INFO] 
[2020-01-14 12:53:01][log.py][line:58][INFO] 发送账号【ss13126325@sina.com】正在发送
[2020-01-14 12:53:01][log.py][line:58][INFO] 接受序号【96】【74810909@qq.com】发送成功
[2020-01-14 12:53:01][log.py][line:58][INFO] 
[2020-01-14 12:55:32][log.py][line:68][ERROR] 产生错误于：【 bivzq3211jw@126.com】发送失败
[2020-01-14 12:55:32][log.py][line:68][ERROR] (535, b'Error: authentication failed')
[2020-01-14 12:55:32][log.py][line:58][INFO] 
[2020-01-14 12:55:34][log.py][line:58][INFO] 发送账号【ss13126325@sina.com】正在发送
[2020-01-14 12:55:34][log.py][line:58][INFO] 接受序号【97】【16233176@qq.com】发送成功
[2020-01-14 12:55:34][log.py][line:58][INFO] 
[2020-01-14 12:58:06][log.py][line:58][INFO] 发送账号【fhbcb9177ww@126.com】正在发送
[2020-01-14 12:58:06][log.py][line:58][INFO] 接受序号【98】【86579234@qq.com】发送成功
[2020-01-14 12:58:06][log.py][line:58][INFO] 
[2020-01-14 13:00:39][log.py][line:58][INFO] 发送账号【okrbh0857wq@126.com】正在发送
[2020-01-14 13:00:39][log.py][line:58][INFO] 接受序号【99】【60954424@qq.com】发送成功
[2020-01-14 13:00:39][log.py][line:58][INFO] 
[2020-01-14 13:03:10][log.py][line:68][ERROR] 产生错误于：【enh915@163.com】发送失败
[2020-01-14 13:03:10][log.py][line:68][ERROR] (550, b'User has no permission')
[2020-01-14 13:03:10][log.py][line:58][INFO] 
[2020-01-14 13:03:12][log.py][line:58][INFO] 发送账号【ss13126325@sina.com】正在发送
[2020-01-14 13:03:12][log.py][line:58][INFO] 接受序号【100】【30893042@qq.com】发送成功
[2020-01-14 13:03:12][log.py][line:58][INFO] 
[2020-01-14 13:05:44][log.py][line:68][ERROR] 产生错误于：【x6r344@163.com】发送失败
[2020-01-14 13:05:44][log.py][line:68][ERROR] (550, b'User has no permission')
[2020-01-14 13:05:44][log.py][line:58][INFO] 
[2020-01-14 13:05:45][log.py][line:58][INFO] 发送账号【atcgk6189iz@126.com】正在发送
[2020-01-14 13:05:45][log.py][line:58][INFO] 接受序号【101】【71329620@qq.com】发送成功
[2020-01-14 13:05:45][log.py][line:58][INFO] 
[2020-01-14 13:08:16][log.py][line:68][ERROR] 产生错误于：【p6596v@163.com】发送失败
[2020-01-14 13:08:16][log.py][line:68][ERROR] (550, b'User has no permission')
[2020-01-14 13:08:16][log.py][line:58][INFO] 
[2020-01-14 13:08:18][log.py][line:68][ERROR] 产生错误于：【iao443@163.com】发送失败
[2020-01-14 13:08:18][log.py][line:68][ERROR] (550, b'User has no permission')
[2020-01-14 13:08:18][log.py][line:58][INFO] 
[2020-01-14 13:08:20][log.py][line:58][INFO] 发送账号【libgi0133jx@126.com】正在发送
[2020-01-14 13:08:20][log.py][line:58][INFO] 接受序号【102】【25309931@qq.com】发送成功
[2020-01-14 13:08:20][log.py][line:58][INFO] 
[2020-01-14 13:10:52][log.py][line:58][INFO] 发送账号【ucvbg3292qd@126.com】正在发送
[2020-01-14 13:10:52][log.py][line:58][INFO] 接受序号【103】【51074991@qq.com】发送成功
[2020-01-14 13:10:52][log.py][line:58][INFO] 
[2020-01-14 13:13:23][log.py][line:58][INFO] 发送账号【icvma2101ry@126.com】正在发送
[2020-01-14 13:13:23][log.py][line:58][INFO] 接受序号【104】【19590592@qq.com】发送成功
[2020-01-14 13:13:23][log.py][line:58][INFO] 
[2020-01-14 13:15:56][log.py][line:58][INFO] 发送账号【gv576m@163.com】正在发送
[2020-01-14 13:15:56][log.py][line:58][INFO] 接受序号【105】【89252696@qq.com】发送成功
[2020-01-14 13:15:56][log.py][line:58][INFO] 
[2020-01-14 13:18:28][log.py][line:58][INFO] 发送账号【a0i5me@163.com】正在发送
[2020-01-14 13:18:28][log.py][line:58][INFO] 接受序号【106】【81249406@qq.com】发送成功
[2020-01-14 13:18:28][log.py][line:58][INFO] 
[2020-01-14 13:21:00][log.py][line:68][ERROR] 产生错误于：【vjz463@163.com】发送失败
[2020-01-14 13:21:00][log.py][line:68][ERROR] (550, b'User has no permission')
[2020-01-14 13:21:00][log.py][line:58][INFO] 
[2020-01-14 13:21:03][log.py][line:58][INFO] 发送账号【ss13126325@sina.com】正在发送
[2020-01-14 13:21:03][log.py][line:58][INFO] 接受序号【107】【83568078@qq.com】发送成功
[2020-01-14 13:21:03][log.py][line:58][INFO] 
[2020-01-14 13:23:35][log.py][line:68][ERROR] 产生错误于：【s5f96l@163.com】发送失败
[2020-01-14 13:23:35][log.py][line:68][ERROR] 'ascii' codec can't encode character '\xa0' in position 22: ordinal not in range(128)
[2020-01-14 13:23:35][log.py][line:58][INFO] 
[2020-01-14 13:23:38][log.py][line:58][INFO] 发送账号【qbb075@163.com】正在发送
[2020-01-14 13:23:38][log.py][line:58][INFO] 接受序号【108】【66993341@qq.com】发送成功
[2020-01-14 13:23:38][log.py][line:58][INFO] 
[2020-01-14 13:26:10][log.py][line:58][INFO] 发送账号【zd69x1@163.com】正在发送
[2020-01-14 13:26:10][log.py][line:58][INFO] 接受序号【109】【36140632@qq.com】发送成功
[2020-01-14 13:26:10][log.py][line:58][INFO] 
[2020-01-14 13:28:43][log.py][line:58][INFO] 发送账号【ciema0687mt@126.com】正在发送
[2020-01-14 13:28:43][log.py][line:58][INFO] 接受序号【110】【47433661@qq.com】发送成功
[2020-01-14 13:28:43][log.py][line:58][INFO] 
[2020-01-14 13:31:15][log.py][line:58][INFO] 发送账号【ss13126325@sina.com】正在发送
[2020-01-14 13:31:15][log.py][line:58][INFO] 接受序号【111】【17503552@qq.com】发送成功
[2020-01-14 13:31:15][log.py][line:58][INFO] 
[2020-01-14 13:33:52][log.py][line:68][ERROR] 产生错误于：【nvz94n@163.com】发送失败
[2020-01-14 13:33:52][log.py][line:68][ERROR] (535, b'Error: authentication failed')
[2020-01-14 13:33:52][log.py][line:58][INFO] 
[2020-01-14 13:33:59][log.py][line:68][ERROR] 产生错误于：【ngj288@163.com】发送失败
[2020-01-14 13:33:59][log.py][line:68][ERROR] (550, b'User has no permission')
[2020-01-14 13:33:59][log.py][line:58][INFO] 
[2020-01-14 13:34:01][log.py][line:58][INFO] 发送账号【faeov5634yr@126.com】正在发送
[2020-01-14 13:34:01][log.py][line:58][INFO] 接受序号【112】【45410130@qq.com】发送成功
[2020-01-14 13:34:01][log.py][line:58][INFO] 
[2020-01-14 13:36:32][log.py][line:58][INFO] 发送账号【ss13126325@sina.com】正在发送
[2020-01-14 13:36:32][log.py][line:58][INFO] 接受序号【113】【44904419@qq.com】发送成功
[2020-01-14 13:36:32][log.py][line:58][INFO] 
[2020-01-14 13:39:10][log.py][line:68][ERROR] 产生错误于：【avy565@163.com】发送失败
[2020-01-14 13:39:10][log.py][line:68][ERROR] (550, b'User has no permission')
[2020-01-14 13:39:10][log.py][line:58][INFO] 
[2020-01-14 13:39:19][log.py][line:68][ERROR] 产生错误于：【fp29x8@163.com】发送失败
[2020-01-14 13:39:19][log.py][line:68][ERROR] (550, b'User has no permission')
[2020-01-14 13:39:19][log.py][line:58][INFO] 
[2020-01-14 13:39:22][log.py][line:58][INFO] 发送账号【erlng1553pe@126.com】正在发送
[2020-01-14 13:39:22][log.py][line:58][INFO] 接受序号【114】【53877041@qq.com】发送成功
[2020-01-14 13:39:22][log.py][line:58][INFO] 
[2020-01-14 13:42:01][log.py][line:68][ERROR] 产生错误于：【ida649@163.com】发送失败
[2020-01-14 13:42:01][log.py][line:68][ERROR] (550, b'User has no permission')
[2020-01-14 13:42:01][log.py][line:58][INFO] 
[2020-01-14 13:42:11][log.py][line:58][INFO] 发送账号【bl21q6@163.com】正在发送
[2020-01-14 13:42:11][log.py][line:58][INFO] 接受序号【115】【02549352@qq.com】发送成功
[2020-01-14 13:42:11][log.py][line:58][INFO] 
[2020-01-14 13:44:50][log.py][line:58][INFO] 发送账号【hahtjm@163.com】正在发送
[2020-01-14 13:44:50][log.py][line:58][INFO] 接受序号【116】【00763285@qq.com】发送成功
[2020-01-14 13:44:50][log.py][line:58][INFO] 
[2020-01-14 13:47:29][log.py][line:58][INFO] 发送账号【j2g6h9@163.com】正在发送
[2020-01-14 13:47:29][log.py][line:58][INFO] 接受序号【117】【62437079@qq.com】发送成功
[2020-01-14 13:47:29][log.py][line:58][INFO] 
[2020-01-14 13:50:02][log.py][line:58][INFO] 发送账号【erlng1553pe@126.com】正在发送
[2020-01-14 13:50:02][log.py][line:58][INFO] 接受序号【118】【28035427@qq.com】发送成功
[2020-01-14 13:50:02][log.py][line:58][INFO] 
[2020-01-14 13:52:33][log.py][line:68][ERROR] 产生错误于：【l7vagn@163.com】发送失败
[2020-01-14 13:52:33][log.py][line:68][ERROR] (550, b'User has no permission')
[2020-01-14 13:52:33][log.py][line:58][INFO] 
[2020-01-14 13:52:35][log.py][line:68][ERROR] 产生错误于：【osl908@163.com】发送失败
[2020-01-14 13:52:35][log.py][line:68][ERROR] (550, b'User has no permission')
[2020-01-14 13:52:35][log.py][line:58][INFO] 
[2020-01-14 13:52:37][log.py][line:58][INFO] 发送账号【ss13126325@sina.com】正在发送
[2020-01-14 13:52:37][log.py][line:58][INFO] 接受序号【119】【58430527@qq.com】发送成功
[2020-01-14 13:52:37][log.py][line:58][INFO] 
[2020-01-14 13:55:08][log.py][line:58][INFO] 发送账号【ss13126325@sina.com】正在发送
[2020-01-14 13:55:08][log.py][line:58][INFO] 接受序号【120】【03985725@qq.com】发送成功
[2020-01-14 13:55:08][log.py][line:58][INFO] 
[2020-01-14 13:57:40][log.py][line:58][INFO] 发送账号【srpom5910bc@126.com】正在发送
[2020-01-14 13:57:40][log.py][line:58][INFO] 接受序号【121】【67485812@qq.com】发送成功
[2020-01-14 13:57:40][log.py][line:58][INFO] 
[2020-01-14 14:00:16][log.py][line:58][INFO] 发送账号【aec3yk@163.com】正在发送
[2020-01-14 14:00:16][log.py][line:58][INFO] 接受序号【122】【83858305@qq.com】发送成功
[2020-01-14 14:00:16][log.py][line:58][INFO] 
[2020-01-14 14:02:48][log.py][line:58][INFO] 发送账号【ykgfw0041ei@126.com】正在发送
[2020-01-14 14:02:48][log.py][line:58][INFO] 接受序号【123】【74615251@qq.com】发送成功
[2020-01-14 14:02:48][log.py][line:58][INFO] 
[2020-01-14 14:05:24][log.py][line:58][INFO] 发送账号【n4681f@163.com】正在发送
[2020-01-14 14:05:24][log.py][line:58][INFO] 接受序号【124】【25281506@qq.com】发送成功
[2020-01-14 14:05:24][log.py][line:58][INFO] 
[2020-01-14 14:07:55][log.py][line:58][INFO] 发送账号【kemcl0763gk@126.com】正在发送
[2020-01-14 14:07:55][log.py][line:58][INFO] 接受序号【125】【48450900@qq.com】发送成功
[2020-01-14 14:07:55][log.py][line:58][INFO] 
[2020-01-14 14:10:30][log.py][line:68][ERROR] 产生错误于：【uzt515@163.com】发送失败
[2020-01-14 14:10:30][log.py][line:68][ERROR] (550, b'User has no permission')
[2020-01-14 14:10:30][log.py][line:58][INFO] 
[2020-01-14 14:10:35][log.py][line:58][INFO] 发送账号【al51g0@163.com】正在发送
[2020-01-14 14:10:35][log.py][line:58][INFO] 接受序号【126】【42759895@qq.com】发送成功
[2020-01-14 14:10:35][log.py][line:58][INFO] 
[2020-01-14 14:13:06][log.py][line:58][INFO] 发送账号【fyk7sc@163.com】正在发送
[2020-01-14 14:13:06][log.py][line:58][INFO] 接受序号【127】【11501397@qq.com】发送成功
[2020-01-14 14:13:06][log.py][line:58][INFO] 
[2020-01-14 14:15:38][log.py][line:68][ERROR] 产生错误于：【 jtj3l5@163.com】发送失败
[2020-01-14 14:15:38][log.py][line:68][ERROR] (535, b'Error: authentication failed')
[2020-01-14 14:15:38][log.py][line:58][INFO] 
[2020-01-14 14:15:41][log.py][line:58][INFO] 发送账号【iwpfc440xl@126.com】正在发送
[2020-01-14 14:15:41][log.py][line:58][INFO] 接受序号【128】【03400007@qq.com】发送成功
[2020-01-14 14:15:41][log.py][line:58][INFO] 
[2020-01-14 14:18:12][log.py][line:68][ERROR] 产生错误于：【z7x64r@163.com】发送失败
[2020-01-14 14:18:12][log.py][line:68][ERROR] (550, b'User has no permission')
[2020-01-14 14:18:12][log.py][line:58][INFO] 
[2020-01-14 14:18:13][log.py][line:68][ERROR] 产生错误于：【 yjdvv5943hb@126.com】发送失败
[2020-01-14 14:18:13][log.py][line:68][ERROR] (535, b'Error: authentication failed')
[2020-01-14 14:18:13][log.py][line:58][INFO] 
[2020-01-14 14:18:15][log.py][line:68][ERROR] 产生错误于：【zpd425@163.com】发送失败
[2020-01-14 14:18:15][log.py][line:68][ERROR] (550, b'User has no permission')
[2020-01-14 14:18:15][log.py][line:58][INFO] 
[2020-01-14 14:18:17][log.py][line:68][ERROR] 产生错误于：【m9y48l@163.com】发送失败
[2020-01-14 14:18:17][log.py][line:68][ERROR] (535, b'Error: authentication failed')
[2020-01-14 14:18:17][log.py][line:58][INFO] 
[2020-01-14 14:18:18][log.py][line:68][ERROR] 产生错误于：【 i6m5nh@163.com】发送失败
[2020-01-14 14:18:18][log.py][line:68][ERROR] (535, b'Error: authentication failed')
[2020-01-14 14:18:18][log.py][line:58][INFO] 
[2020-01-14 14:18:20][log.py][line:58][INFO] 发送账号【co84w4@163.com】正在发送
[2020-01-14 14:18:20][log.py][line:58][INFO] 接受序号【129】【11718063@qq.com】发送成功
[2020-01-14 14:18:20][log.py][line:58][INFO] 
[2020-01-14 14:20:52][log.py][line:68][ERROR] 产生错误于：【gem385@163.com】发送失败
[2020-01-14 14:20:52][log.py][line:68][ERROR] (550, b'User has no permission')
[2020-01-14 14:20:52][log.py][line:58][INFO] 
[2020-01-14 14:20:53][log.py][line:68][ERROR] 产生错误于：【vjbkrc@163.com】发送失败
[2020-01-14 14:20:53][log.py][line:68][ERROR] (550, b'User has no permission')
[2020-01-14 14:20:53][log.py][line:58][INFO] 
[2020-01-14 14:21:17][log.py][line:58][INFO] 发送账号【ss13126325@sina.com】正在发送
[2020-01-14 14:21:17][log.py][line:58][INFO] 接受序号【130】【31747196@qq.com】发送成功
[2020-01-14 14:21:17][log.py][line:58][INFO] 
[2020-01-14 14:23:48][log.py][line:58][INFO] 发送账号【xhpky2744ej@126.com】正在发送
[2020-01-14 14:23:48][log.py][line:58][INFO] 接受序号【131】【94917067@qq.com】发送成功
[2020-01-14 14:23:48][log.py][line:58][INFO] 
[2020-01-14 14:26:23][log.py][line:68][ERROR] 产生错误于：【otf266@163.com】发送失败
[2020-01-14 14:26:23][log.py][line:68][ERROR] (550, b'User has no permission')
[2020-01-14 14:26:23][log.py][line:58][INFO] 
[2020-01-14 14:26:27][log.py][line:58][INFO] 发送账号【zr96np@163.com】正在发送
[2020-01-14 14:26:27][log.py][line:58][INFO] 接受序号【132】【50068985@qq.com】发送成功
[2020-01-14 14:26:27][log.py][line:58][INFO] 
[2020-01-14 14:28:59][log.py][line:68][ERROR] 产生错误于：【p501te@163.com】发送失败
[2020-01-14 14:28:59][log.py][line:68][ERROR] (550, b'User has no permission')
[2020-01-14 14:28:59][log.py][line:58][INFO] 
[2020-01-14 14:29:01][log.py][line:68][ERROR] 产生错误于：【uys951@163.com】发送失败
[2020-01-14 14:29:01][log.py][line:68][ERROR] (550, b'User has no permission')
[2020-01-14 14:29:01][log.py][line:58][INFO] 
[2020-01-14 14:29:03][log.py][line:58][INFO] 发送账号【kbu1dc@163.com】正在发送
[2020-01-14 14:29:03][log.py][line:58][INFO] 接受序号【133】【42101065@qq.com】发送成功
[2020-01-14 14:29:03][log.py][line:58][INFO] 
[2020-01-14 14:31:34][log.py][line:58][INFO] 发送账号【e5l8g7@163.com】正在发送
[2020-01-14 14:31:34][log.py][line:58][INFO] 接受序号【134】【07505412@qq.com】发送成功
[2020-01-14 14:31:34][log.py][line:58][INFO] 
[2020-01-14 14:34:06][log.py][line:58][INFO] 发送账号【zz48r3@163.com】正在发送
[2020-01-14 14:34:06][log.py][line:58][INFO] 接受序号【135】【04736923@qq.com】发送成功
[2020-01-14 14:34:06][log.py][line:58][INFO] 
[2020-01-14 14:36:38][log.py][line:58][INFO] 发送账号【ss13126325@sina.com】正在发送
[2020-01-14 14:36:38][log.py][line:58][INFO] 接受序号【136】【22475328@qq.com】发送成功
[2020-01-14 14:36:38][log.py][line:58][INFO] 
[2020-01-14 14:39:09][log.py][line:58][INFO] 发送账号【ss13126325@sina.com】正在发送
[2020-01-14 14:39:09][log.py][line:58][INFO] 接受序号【137】【01540799@qq.com】发送成功
[2020-01-14 14:39:09][log.py][line:58][INFO] 
[2020-01-14 14:40:29][log.py][line:58][INFO] 
[2020-01-14 14:40:29][log.py][line:58][INFO] 脚本开始------------------------------------------------------------------
[2020-01-14 14:40:30][log.py][line:68][ERROR] 产生错误于：【fhn664@163.com】发送失败
[2020-01-14 14:40:30][log.py][line:68][ERROR] (550, b'User has no permission')
[2020-01-14 14:40:30][log.py][line:58][INFO] 
[2020-01-14 14:40:32][log.py][line:58][INFO] 发送账号【ss13126325@sina.com】正在发送
[2020-01-14 14:40:32][log.py][line:58][INFO] 接受序号【1】【94246029@qq.com】发送成功
[2020-01-14 14:40:32][log.py][line:58][INFO] 
[2020-01-14 14:43:13][log.py][line:68][ERROR] 产生错误于：【dux277@163.com】发送失败
[2020-01-14 14:43:13][log.py][line:68][ERROR] (550, b'User has no permission')
[2020-01-14 14:43:13][log.py][line:58][INFO] 
[2020-01-14 14:43:31][log.py][line:68][ERROR] 产生错误于：【ja70EZ@163.com】发送失败
[2020-01-14 14:43:31][log.py][line:68][ERROR] (550, b'User has no permission')
[2020-01-14 14:43:31][log.py][line:58][INFO] 
[2020-01-14 14:43:33][log.py][line:58][INFO] 发送账号【uu24680644@126.com】正在发送
[2020-01-14 14:43:33][log.py][line:58][INFO] 接受序号【2】【48662817@qq.com】发送成功
[2020-01-14 14:43:33][log.py][line:58][INFO] 
[2020-01-14 14:46:12][log.py][line:68][ERROR] 产生错误于：【hqmayv@163.com】发送失败
[2020-01-14 14:46:12][log.py][line:68][ERROR] (550, b'User has no permission')
[2020-01-14 14:46:12][log.py][line:58][INFO] 
[2020-01-14 14:46:14][log.py][line:58][INFO] 发送账号【ezjsh7913yb@126.com】正在发送
[2020-01-14 14:46:14][log.py][line:58][INFO] 接受序号【3】【81006245@qq.com】发送成功
[2020-01-14 14:46:14][log.py][line:58][INFO] 
[2020-01-14 14:48:53][log.py][line:68][ERROR] 产生错误于：【 kvl1z7@163.com】发送失败
[2020-01-14 14:48:53][log.py][line:68][ERROR] (535, b'Error: authentication failed')
[2020-01-14 14:48:53][log.py][line:58][INFO] 
[2020-01-14 14:49:03][log.py][line:58][INFO] 发送账号【k737jk@163.com】正在发送
[2020-01-14 14:49:03][log.py][line:58][INFO] 接受序号【4】【86113242@qq.com】发送成功
[2020-01-14 14:49:03][log.py][line:58][INFO] 
[2020-01-14 14:51:35][log.py][line:58][INFO] 发送账号【bqasq3282ug@126.com】正在发送
[2020-01-14 14:51:35][log.py][line:58][INFO] 接受序号【5】【17269900@qq.com】发送成功
[2020-01-14 14:51:35][log.py][line:58][INFO] 
[2020-01-14 14:54:07][log.py][line:58][INFO] 发送账号【ciema0687mt@126.com】正在发送
[2020-01-14 14:54:07][log.py][line:58][INFO] 接受序号【6】【08675843@qq.com】发送成功
[2020-01-14 14:54:07][log.py][line:58][INFO] 
[2020-01-14 14:56:48][log.py][line:68][ERROR] 产生错误于：【b018n4@163.com】发送失败
[2020-01-14 14:56:48][log.py][line:68][ERROR] (550, b'User has no permission')
[2020-01-14 14:56:48][log.py][line:58][INFO] 
[2020-01-14 14:56:58][log.py][line:58][INFO] 发送账号【nah5ae@163.com】正在发送
[2020-01-14 14:56:58][log.py][line:58][INFO] 接受序号【7】【41927833@qq.com】发送成功
[2020-01-14 14:56:58][log.py][line:58][INFO] 
[2020-01-14 14:59:37][log.py][line:58][INFO] 发送账号【o6n553@163.com】正在发送
[2020-01-14 14:59:37][log.py][line:58][INFO] 接受序号【8】【30720145@qq.com】发送成功
[2020-01-14 14:59:37][log.py][line:58][INFO] 
[2020-01-14 15:02:08][log.py][line:68][ERROR] 产生错误于：【 lvfja7380rj@126.com】发送失败
[2020-01-14 15:02:08][log.py][line:68][ERROR] (535, b'Error: authentication failed')
[2020-01-14 15:02:08][log.py][line:58][INFO] 
[2020-01-14 15:02:10][log.py][line:58][INFO] 发送账号【ucr2ue@163.com】正在发送
[2020-01-14 15:02:10][log.py][line:58][INFO] 接受序号【9】【52630344@qq.com】发送成功
[2020-01-14 15:02:10][log.py][line:58][INFO] 
[2020-01-14 15:04:41][log.py][line:68][ERROR] 产生错误于：【ypn172@163.com】发送失败
[2020-01-14 15:04:41][log.py][line:68][ERROR] (550, b'User has no permission')
[2020-01-14 15:04:41][log.py][line:58][INFO] 
[2020-01-14 15:04:44][log.py][line:58][INFO] 发送账号【ss13126325@sina.com】正在发送
[2020-01-14 15:04:44][log.py][line:58][INFO] 接受序号【10】【46777624@qq.com】发送成功
[2020-01-14 15:04:44][log.py][line:58][INFO] 
[2020-01-14 15:07:15][log.py][line:68][ERROR] 产生错误于：【y77xz3@163.com】发送失败
[2020-01-14 15:07:15][log.py][line:68][ERROR] (550, b'User has no permission')
[2020-01-14 15:07:15][log.py][line:58][INFO] 
[2020-01-14 15:07:20][log.py][line:58][INFO] 发送账号【ss13126325@sina.com】正在发送
[2020-01-14 15:07:20][log.py][line:58][INFO] 接受序号【11】【64465155@qq.com】发送成功
[2020-01-14 15:07:20][log.py][line:58][INFO] 
[2020-01-14 15:09:52][log.py][line:68][ERROR] 产生错误于：【orq170@163.com】发送失败
[2020-01-14 15:09:52][log.py][line:68][ERROR] (550, b'User has no permission')
[2020-01-14 15:09:52][log.py][line:58][INFO] 
[2020-01-14 15:09:54][log.py][line:58][INFO] 发送账号【ss13126325@sina.com】正在发送
[2020-01-14 15:09:54][log.py][line:58][INFO] 接受序号【12】【10526691@qq.com】发送成功
[2020-01-14 15:09:54][log.py][line:58][INFO] 
[2020-01-14 15:12:27][log.py][line:68][ERROR] 产生错误于：【 afdfs7892io@126.com】发送失败
[2020-01-14 15:12:27][log.py][line:68][ERROR] (535, b'Error: authentication failed')
[2020-01-14 15:12:27][log.py][line:58][INFO] 
[2020-01-14 15:12:29][log.py][line:68][ERROR] 产生错误于：【oke20z@163.com】发送失败
[2020-01-14 15:12:29][log.py][line:68][ERROR] (550, b'User has no permission')
[2020-01-14 15:12:29][log.py][line:58][INFO] 
[2020-01-14 15:12:31][log.py][line:68][ERROR] 产生错误于：【xdl582@163.com】发送失败
[2020-01-14 15:12:31][log.py][line:68][ERROR] (550, b'User has no permission')
[2020-01-14 15:12:31][log.py][line:58][INFO] 
[2020-01-14 15:12:33][log.py][line:68][ERROR] 产生错误于：【tby917@163.com】发送失败
[2020-01-14 15:12:33][log.py][line:68][ERROR] (550, b'User has no permission')
[2020-01-14 15:12:33][log.py][line:58][INFO] 
[2020-01-14 15:12:35][log.py][line:58][INFO] 发送账号【ss13126325@sina.com】正在发送
[2020-01-14 15:12:35][log.py][line:58][INFO] 接受序号【13】【03732767@qq.com】发送成功
[2020-01-14 15:12:35][log.py][line:58][INFO] 
[2020-01-14 15:15:09][log.py][line:58][INFO] 发送账号【mwk2h8@163.com】正在发送
[2020-01-14 15:15:09][log.py][line:58][INFO] 接受序号【14】【77207427@qq.com】发送成功
[2020-01-14 15:15:09][log.py][line:58][INFO] 
[2020-01-14 15:17:41][log.py][line:58][INFO] 发送账号【ofaxp0781kr@126.com】正在发送
[2020-01-14 15:17:41][log.py][line:58][INFO] 接受序号【15】【84445959@qq.com】发送成功
[2020-01-14 15:17:41][log.py][line:58][INFO] 
[2020-01-14 15:20:15][log.py][line:58][INFO] 发送账号【fmb72b@163.com】正在发送
[2020-01-14 15:20:15][log.py][line:58][INFO] 接受序号【16】【94746227@qq.com】发送成功
[2020-01-14 15:20:15][log.py][line:58][INFO] 
[2020-01-14 15:22:47][log.py][line:58][INFO] 发送账号【jmd597@163.com】正在发送
[2020-01-14 15:22:47][log.py][line:58][INFO] 接受序号【17】【08725038@qq.com】发送成功
[2020-01-14 15:22:47][log.py][line:58][INFO] 
[2020-01-14 15:25:20][log.py][line:68][ERROR] 产生错误于：【 a494ua@163.com】发送失败
[2020-01-14 15:25:20][log.py][line:68][ERROR] (535, b'Error: authentication failed')
[2020-01-14 15:25:20][log.py][line:58][INFO] 
[2020-01-14 15:25:31][log.py][line:58][INFO] 发送账号【ss13126325@sina.com】正在发送
[2020-01-14 15:25:31][log.py][line:58][INFO] 接受序号【18】【90449577@qq.com】发送成功
[2020-01-14 15:25:31][log.py][line:58][INFO] 
[2020-01-14 15:28:04][log.py][line:68][ERROR] 产生错误于：【ysd599@163.com】发送失败
[2020-01-14 15:28:04][log.py][line:68][ERROR] (550, b'User has no permission')
[2020-01-14 15:28:04][log.py][line:58][INFO] 
[2020-01-14 15:28:06][log.py][line:68][ERROR] 产生错误于：【 rkmym8552vj@126.com】发送失败
[2020-01-14 15:28:06][log.py][line:68][ERROR] (535, b'Error: authentication failed')
[2020-01-14 15:28:06][log.py][line:58][INFO] 
[2020-01-14 15:28:07][log.py][line:68][ERROR] 产生错误于：【 lvfja7380rj@126.com】发送失败
[2020-01-14 15:28:07][log.py][line:68][ERROR] (535, b'Error: authentication failed')
[2020-01-14 15:28:07][log.py][line:58][INFO] 
[2020-01-14 15:28:09][log.py][line:58][INFO] 发送账号【wcqta7018af@126.com】正在发送
[2020-01-14 15:28:09][log.py][line:58][INFO] 接受序号【19】【71685282@qq.com】发送成功
[2020-01-14 15:28:09][log.py][line:58][INFO] 
[2020-01-14 15:30:41][log.py][line:58][INFO] 发送账号【ss13126325@sina.com】正在发送
[2020-01-14 15:30:41][log.py][line:58][INFO] 接受序号【20】【05805571@qq.com】发送成功
[2020-01-14 15:30:41][log.py][line:58][INFO] 
[2020-01-14 15:33:13][log.py][line:68][ERROR] 产生错误于：【iap713@163.com】发送失败
[2020-01-14 15:33:13][log.py][line:68][ERROR] (550, b'User has no permission')
[2020-01-14 15:33:13][log.py][line:58][INFO] 
[2020-01-14 15:33:15][log.py][line:58][INFO] 发送账号【ss13126325@sina.com】正在发送
[2020-01-14 15:33:15][log.py][line:58][INFO] 接受序号【21】【75894966@qq.com】发送成功
[2020-01-14 15:33:15][log.py][line:58][INFO] 
[2020-01-14 15:35:46][log.py][line:68][ERROR] 产生错误于：【ine278@163.com】发送失败
[2020-01-14 15:35:46][log.py][line:68][ERROR] (550, b'User has no permission')
[2020-01-14 15:35:46][log.py][line:58][INFO] 
[2020-01-14 15:35:47][log.py][line:58][INFO] 发送账号【smbnh6865dm@126.com】正在发送
[2020-01-14 15:35:47][log.py][line:58][INFO] 接受序号【22】【34175581@qq.com】发送成功
[2020-01-14 15:35:47][log.py][line:58][INFO] 
[2020-01-14 15:38:19][log.py][line:58][INFO] 发送账号【kff22c@163.com】正在发送
[2020-01-14 15:38:19][log.py][line:58][INFO] 接受序号【23】【51957306@qq.com】发送成功
[2020-01-14 15:38:19][log.py][line:58][INFO] 
[2020-01-14 15:40:51][log.py][line:68][ERROR] 产生错误于：【5lgh7@163.com】发送失败
[2020-01-14 15:40:51][log.py][line:68][ERROR] (535, b'Error: authentication failed')
[2020-01-14 15:40:51][log.py][line:58][INFO] 
[2020-01-14 15:40:53][log.py][line:58][INFO] 发送账号【ss13126325@sina.com】正在发送
[2020-01-14 15:40:53][log.py][line:58][INFO] 接受序号【24】【92335861@qq.com】发送成功
[2020-01-14 15:40:53][log.py][line:58][INFO] 
[2020-01-14 15:43:24][log.py][line:58][INFO] 发送账号【ss13126325@sina.com】正在发送
[2020-01-14 15:43:24][log.py][line:58][INFO] 接受序号【25】【76146889@qq.com】发送成功
[2020-01-14 15:43:24][log.py][line:58][INFO] 
[2020-01-14 15:45:57][log.py][line:58][INFO] 发送账号【ryoqf0834bs@126.com】正在发送
[2020-01-14 15:45:57][log.py][line:58][INFO] 接受序号【26】【01553319@qq.com】发送成功
[2020-01-14 15:45:57][log.py][line:58][INFO] 
[2020-01-14 15:48:28][log.py][line:68][ERROR] 产生错误于：【wpz248@163.com】发送失败
[2020-01-14 15:48:28][log.py][line:68][ERROR] (550, b'User has no permission')
[2020-01-14 15:48:28][log.py][line:58][INFO] 
[2020-01-14 15:48:30][log.py][line:58][INFO] 发送账号【sk248028226@126.com】正在发送
[2020-01-14 15:48:30][log.py][line:58][INFO] 接受序号【27】【67282143@qq.com】发送成功
[2020-01-14 15:48:30][log.py][line:58][INFO] 
[2020-01-14 15:51:01][log.py][line:68][ERROR] 产生错误于：【kws738@163.com】发送失败
[2020-01-14 15:51:01][log.py][line:68][ERROR] (550, b'User has no permission')
[2020-01-14 15:51:01][log.py][line:58][INFO] 
[2020-01-14 15:51:03][log.py][line:58][INFO] 发送账号【u4s658@163.com】正在发送
[2020-01-14 15:51:03][log.py][line:58][INFO] 接受序号【28】【45979235@qq.com】发送成功
[2020-01-14 15:51:03][log.py][line:58][INFO] 
[2020-01-14 15:53:35][log.py][line:58][INFO] 发送账号【ibqhn0074ck@126.com】正在发送
[2020-01-14 15:53:35][log.py][line:58][INFO] 接受序号【29】【23786807@qq.com】发送成功
[2020-01-14 15:53:35][log.py][line:58][INFO] 
[2020-01-14 15:56:06][log.py][line:58][INFO] 发送账号【bl21q6@163.com】正在发送
[2020-01-14 15:56:06][log.py][line:58][INFO] 接受序号【30】【78943332@qq.com】发送成功
[2020-01-14 15:56:06][log.py][line:58][INFO] 
[2020-01-14 15:58:38][log.py][line:58][INFO] 发送账号【urt6ca@163.com】正在发送
[2020-01-14 15:58:38][log.py][line:58][INFO] 接受序号【31】【61398096@qq.com】发送成功
[2020-01-14 15:58:38][log.py][line:58][INFO] 
[2020-01-14 16:01:10][log.py][line:58][INFO] 发送账号【qvgxd8220mk@126.com】正在发送
[2020-01-14 16:01:10][log.py][line:58][INFO] 接受序号【32】【29638765@qq.com】发送成功
[2020-01-14 16:01:10][log.py][line:58][INFO] 
[2020-01-14 16:03:41][log.py][line:68][ERROR] 产生错误于：【 lds1pv@163.com】发送失败
[2020-01-14 16:03:41][log.py][line:68][ERROR] (535, b'Error: authentication failed')
[2020-01-14 16:03:41][log.py][line:58][INFO] 
[2020-01-14 16:03:43][log.py][line:58][INFO] 发送账号【ss13126325@sina.com】正在发送
[2020-01-14 16:03:43][log.py][line:58][INFO] 接受序号【33】【99681469@qq.com】发送成功
[2020-01-14 16:03:43][log.py][line:58][INFO] 
[2020-01-14 16:06:15][log.py][line:58][INFO] 发送账号【ss13126325@sina.com】正在发送
[2020-01-14 16:06:15][log.py][line:58][INFO] 接受序号【34】【48023909@qq.com】发送成功
[2020-01-14 16:06:15][log.py][line:58][INFO] 
[2020-01-14 16:08:46][log.py][line:68][ERROR] 产生错误于：【 ki09kt@163.com】发送失败
[2020-01-14 16:08:46][log.py][line:68][ERROR] (535, b'Error: authentication failed')
[2020-01-14 16:08:46][log.py][line:58][INFO] 
[2020-01-14 16:08:48][log.py][line:58][INFO] 发送账号【ss13126325@sina.com】正在发送
[2020-01-14 16:08:48][log.py][line:58][INFO] 接受序号【35】【71888621@qq.com】发送成功
[2020-01-14 16:08:48][log.py][line:58][INFO] 
[2020-01-14 16:11:19][log.py][line:68][ERROR] 产生错误于：【rqy245@163.com】发送失败
[2020-01-14 16:11:19][log.py][line:68][ERROR] (550, b'User has no permission')
[2020-01-14 16:11:19][log.py][line:58][INFO] 
[2020-01-14 16:11:20][log.py][line:68][ERROR] 产生错误于：【tyr177@163.com】发送失败
[2020-01-14 16:11:20][log.py][line:68][ERROR] (550, b'User has no permission')
[2020-01-14 16:11:20][log.py][line:58][INFO] 
[2020-01-14 16:11:22][log.py][line:58][INFO] 发送账号【ss13126325@sina.com】正在发送
[2020-01-14 16:11:22][log.py][line:58][INFO] 接受序号【36】【89102090@qq.com】发送成功
[2020-01-14 16:11:22][log.py][line:58][INFO] 
[2020-01-14 16:13:54][log.py][line:58][INFO] 发送账号【ss13126325@sina.com】正在发送
[2020-01-14 16:13:54][log.py][line:58][INFO] 接受序号【37】【81757009@qq.com】发送成功
[2020-01-14 16:13:54][log.py][line:58][INFO] 
[2020-01-14 16:18:09][log.py][line:68][ERROR] 产生错误于：【ss13126325@sina.com】发送失败
[2020-01-14 16:18:09][log.py][line:68][ERROR] [WinError 10060] 由于连接方在一段时间后没有正确答复或连接的主机没有反应，连接尝试失败。
[2020-01-14 16:18:09][log.py][line:58][INFO] 
[2020-01-14 16:18:32][log.py][line:68][ERROR] 产生错误于：【wazaf7806mh@126.com】发送失败
[2020-01-14 16:18:32][log.py][line:68][ERROR] [Errno 11001] getaddrinfo failed
[2020-01-14 16:18:32][log.py][line:58][INFO] 
[2020-01-14 16:18:44][log.py][line:68][ERROR] 产生错误于：【d1h8b7@163.com】发送失败
[2020-01-14 16:18:44][log.py][line:68][ERROR] [Errno 11001] getaddrinfo failed
[2020-01-14 16:18:44][log.py][line:58][INFO] 
[2020-01-14 16:18:45][log.py][line:68][ERROR] 产生错误于：【 kvrbg3705pe@126.com】发送失败
[2020-01-14 16:18:45][log.py][line:68][ERROR] [Errno 11001] getaddrinfo failed
[2020-01-14 16:18:45][log.py][line:58][INFO] 
[2020-01-14 16:18:46][log.py][line:68][ERROR] 产生错误于：【fne980@163.com】发送失败
[2020-01-14 16:18:46][log.py][line:68][ERROR] [Errno 11001] getaddrinfo failed
[2020-01-14 16:18:46][log.py][line:58][INFO] 
[2020-01-14 16:18:47][log.py][line:68][ERROR] 产生错误于：【vev591@163.com】发送失败
[2020-01-14 16:18:47][log.py][line:68][ERROR] [Errno 11001] getaddrinfo failed
[2020-01-14 16:18:47][log.py][line:58][INFO] 
[2020-01-14 16:18:48][log.py][line:68][ERROR] 产生错误于：【w8i46z@163.com】发送失败
[2020-01-14 16:18:48][log.py][line:68][ERROR] [Errno 11001] getaddrinfo failed
[2020-01-14 16:18:48][log.py][line:58][INFO] 
[2020-01-14 16:18:48][log.py][line:68][ERROR] 产生错误于：【k929l7@163.com】发送失败
[2020-01-14 16:18:48][log.py][line:68][ERROR] [Errno 11001] getaddrinfo failed
[2020-01-14 16:18:48][log.py][line:58][INFO] 
[2020-01-14 16:18:56][log.py][line:68][ERROR] 产生错误于：【wzp653@163.com】发送失败
[2020-01-14 16:18:56][log.py][line:68][ERROR] [Errno 11001] getaddrinfo failed
[2020-01-14 16:18:56][log.py][line:58][INFO] 
[2020-01-14 16:18:57][log.py][line:68][ERROR] 产生错误于：【aamzc2507bm@126.com】发送失败
[2020-01-14 16:18:57][log.py][line:68][ERROR] [Errno 11001] getaddrinfo failed
[2020-01-14 16:18:57][log.py][line:58][INFO] 
[2020-01-14 16:18:58][log.py][line:68][ERROR] 产生错误于：【fig576@163.com】发送失败
[2020-01-14 16:18:58][log.py][line:68][ERROR] [Errno 11001] getaddrinfo failed
[2020-01-14 16:18:58][log.py][line:58][INFO] 
[2020-01-14 16:18:59][log.py][line:68][ERROR] 产生错误于：【co51hc@163.com】发送失败
[2020-01-14 16:18:59][log.py][line:68][ERROR] [Errno 11001] getaddrinfo failed
[2020-01-14 16:18:59][log.py][line:58][INFO] 
[2020-01-14 16:18:59][log.py][line:68][ERROR] 产生错误于：【b7zxy9@163.com】发送失败
[2020-01-14 16:18:59][log.py][line:68][ERROR] [Errno 11001] getaddrinfo failed
[2020-01-14 16:18:59][log.py][line:58][INFO] 
[2020-01-14 16:19:11][log.py][line:68][ERROR] 产生错误于：【ss13126325@sina.com】发送失败
[2020-01-14 16:19:11][log.py][line:68][ERROR] [Errno 11001] getaddrinfo failed
[2020-01-14 16:19:11][log.py][line:58][INFO] 
[2020-01-14 16:19:12][log.py][line:68][ERROR] 产生错误于：【zz48r3@163.com】发送失败
[2020-01-14 16:19:12][log.py][line:68][ERROR] [Errno 11001] getaddrinfo failed
[2020-01-14 16:19:12][log.py][line:58][INFO] 
[2020-01-14 16:19:23][log.py][line:68][ERROR] 产生错误于：【j614it@163.com】发送失败
[2020-01-14 16:19:23][log.py][line:68][ERROR] [Errno 11001] getaddrinfo failed
[2020-01-14 16:19:23][log.py][line:58][INFO] 
[2020-01-14 16:19:24][log.py][line:68][ERROR] 产生错误于：【kql527@163.com】发送失败
[2020-01-14 16:19:24][log.py][line:68][ERROR] [Errno 11001] getaddrinfo failed
[2020-01-14 16:19:24][log.py][line:58][INFO] 
[2020-01-14 16:19:25][log.py][line:68][ERROR] 产生错误于：【ss13126325@sina.com】发送失败
[2020-01-14 16:19:25][log.py][line:68][ERROR] [Errno 11001] getaddrinfo failed
[2020-01-14 16:19:25][log.py][line:58][INFO] 
[2020-01-14 16:19:26][log.py][line:68][ERROR] 产生错误于：【rwkpq3431ed@126.com】发送失败
[2020-01-14 16:19:26][log.py][line:68][ERROR] [Errno 11001] getaddrinfo failed
[2020-01-14 16:19:26][log.py][line:58][INFO] 
[2020-01-14 16:19:27][log.py][line:68][ERROR] 产生错误于：【ze73ym@163.com】发送失败
[2020-01-14 16:19:27][log.py][line:68][ERROR] [Errno 11001] getaddrinfo failed
[2020-01-14 16:19:27][log.py][line:58][INFO] 
[2020-01-14 16:19:34][log.py][line:68][ERROR] 产生错误于：【q2p8fz@163.com】发送失败
[2020-01-14 16:19:34][log.py][line:68][ERROR] [Errno 11001] getaddrinfo failed
[2020-01-14 16:19:34][log.py][line:58][INFO] 
[2020-01-14 16:19:35][log.py][line:68][ERROR] 产生错误于：【ss13126325@sina.com】发送失败
[2020-01-14 16:19:35][log.py][line:68][ERROR] [Errno 11001] getaddrinfo failed
[2020-01-14 16:19:35][log.py][line:58][INFO] 
[2020-01-14 16:19:36][log.py][line:68][ERROR] 产生错误于：【kdf644@163.com】发送失败
[2020-01-14 16:19:36][log.py][line:68][ERROR] [Errno 11001] getaddrinfo failed
[2020-01-14 16:19:36][log.py][line:58][INFO] 
[2020-01-14 16:19:37][log.py][line:68][ERROR] 产生错误于：【ncx405@163.com】发送失败
[2020-01-14 16:19:37][log.py][line:68][ERROR] [Errno 11001] getaddrinfo failed
[2020-01-14 16:19:37][log.py][line:58][INFO] 
[2020-01-14 16:19:38][log.py][line:68][ERROR] 产生错误于：【xru9g2@163.com】发送失败
[2020-01-14 16:19:38][log.py][line:68][ERROR] [Errno 11001] getaddrinfo failed
[2020-01-14 16:19:38][log.py][line:58][INFO] 
[2020-01-14 16:19:38][log.py][line:68][ERROR] 产生错误于：【ss13126325@sina.com】发送失败
[2020-01-14 16:19:38][log.py][line:68][ERROR] [Errno 11001] getaddrinfo failed
[2020-01-14 16:19:38][log.py][line:58][INFO] 
[2020-01-14 16:19:39][log.py][line:68][ERROR] 产生错误于：【pxkzr1127ao@126.com】发送失败
[2020-01-14 16:19:39][log.py][line:68][ERROR] [Errno 11001] getaddrinfo failed
[2020-01-14 16:19:39][log.py][line:58][INFO] 
[2020-01-14 16:19:46][log.py][line:68][ERROR] 产生错误于：【smbnh6865dm@126.com】发送失败
[2020-01-14 16:19:46][log.py][line:68][ERROR] [Errno 11001] getaddrinfo failed
[2020-01-14 16:19:46][log.py][line:58][INFO] 
[2020-01-14 16:19:47][log.py][line:68][ERROR] 产生错误于：【qtw738@163.com】发送失败
[2020-01-14 16:19:47][log.py][line:68][ERROR] [Errno 11001] getaddrinfo failed
[2020-01-14 16:19:47][log.py][line:58][INFO] 
[2020-01-14 16:19:48][log.py][line:68][ERROR] 产生错误于：【vsv224@163.com】发送失败
[2020-01-14 16:19:48][log.py][line:68][ERROR] [Errno 11001] getaddrinfo failed
[2020-01-14 16:19:48][log.py][line:58][INFO] 
[2020-01-14 16:19:49][log.py][line:68][ERROR] 产生错误于：【ss13126325@sina.com】发送失败
[2020-01-14 16:19:49][log.py][line:68][ERROR] [Errno 11001] getaddrinfo failed
[2020-01-14 16:19:49][log.py][line:58][INFO] 
[2020-01-14 16:19:49][log.py][line:68][ERROR] 产生错误于：【ibqhn0074ck@126.com】发送失败
[2020-01-14 16:19:49][log.py][line:68][ERROR] [Errno 11001] getaddrinfo failed
[2020-01-14 16:19:49][log.py][line:58][INFO] 
[2020-01-14 16:19:50][log.py][line:68][ERROR] 产生错误于：【ao06q0@163.com】发送失败
[2020-01-14 16:19:50][log.py][line:68][ERROR] [Errno 11001] getaddrinfo failed
[2020-01-14 16:19:50][log.py][line:58][INFO] 
[2020-01-14 16:19:58][log.py][line:68][ERROR] 产生错误于：【uzt515@163.com】发送失败
[2020-01-14 16:19:58][log.py][line:68][ERROR] [Errno 11001] getaddrinfo failed
[2020-01-14 16:19:58][log.py][line:58][INFO] 
[2020-01-14 16:19:59][log.py][line:68][ERROR] 产生错误于：【ss13126325@sina.com】发送失败
[2020-01-14 16:19:59][log.py][line:68][ERROR] [Errno 11001] getaddrinfo failed
[2020-01-14 16:19:59][log.py][line:58][INFO] 
[2020-01-14 16:20:00][log.py][line:68][ERROR] 产生错误于：【ss13126325@sina.com】发送失败
[2020-01-14 16:20:00][log.py][line:68][ERROR] [Errno 11001] getaddrinfo failed
[2020-01-14 16:20:00][log.py][line:58][INFO] 
[2020-01-14 16:20:01][log.py][line:68][ERROR] 产生错误于：【pcxmd3459aa@126.com】发送失败
[2020-01-14 16:20:01][log.py][line:68][ERROR] [Errno 11001] getaddrinfo failed
[2020-01-14 16:20:01][log.py][line:58][INFO] 
[2020-01-14 16:20:01][log.py][line:68][ERROR] 产生错误于：【iao443@163.com】发送失败
[2020-01-14 16:20:01][log.py][line:68][ERROR] [Errno 11001] getaddrinfo failed
[2020-01-14 16:20:01][log.py][line:58][INFO] 
[2020-01-14 16:20:02][log.py][line:68][ERROR] 产生错误于：【uzt515@163.com】发送失败
[2020-01-14 16:20:02][log.py][line:68][ERROR] [Errno 11001] getaddrinfo failed
[2020-01-14 16:20:02][log.py][line:58][INFO] 
[2020-01-14 16:20:12][log.py][line:58][INFO] 发送账号【gcv7rk@163.com】正在发送
[2020-01-14 16:20:12][log.py][line:58][INFO] 接受序号【38】【03298221@qq.com】发送成功
[2020-01-14 16:20:12][log.py][line:58][INFO] 
[2020-01-14 16:22:44][log.py][line:58][INFO] 发送账号【vhw6n9@163.com】正在发送
[2020-01-14 16:22:44][log.py][line:58][INFO] 接受序号【39】【57305124@qq.com】发送成功
[2020-01-14 16:22:44][log.py][line:58][INFO] 
[2020-01-14 16:25:15][log.py][line:68][ERROR] 产生错误于：【hqmayv@163.com】发送失败
[2020-01-14 16:25:15][log.py][line:68][ERROR] (550, b'User has no permission')
[2020-01-14 16:25:15][log.py][line:58][INFO] 
[2020-01-14 16:25:17][log.py][line:58][INFO] 发送账号【ss13126325@sina.com】正在发送
[2020-01-14 16:25:17][log.py][line:58][INFO] 接受序号【40】【66936610@qq.com】发送成功
[2020-01-14 16:25:17][log.py][line:58][INFO] 
[2020-01-14 16:35:05][log.py][line:68][ERROR] 产生错误于：【ypn172@163.com】发送失败
[2020-01-14 16:35:05][log.py][line:68][ERROR] (550, b'User has no permission')
[2020-01-14 16:35:05][log.py][line:58][INFO] 
[2020-01-14 16:35:07][log.py][line:68][ERROR] 产生错误于：【txn956@163.com】发送失败
[2020-01-14 16:35:07][log.py][line:68][ERROR] (550, b'User has no permission')
[2020-01-14 16:35:07][log.py][line:58][INFO] 
[2020-01-14 16:35:08][log.py][line:68][ERROR] 产生错误于：【sqx657@163.com】发送失败
[2020-01-14 16:35:08][log.py][line:68][ERROR] (550, b'User has no permission')
[2020-01-14 16:35:08][log.py][line:58][INFO] 
[2020-01-14 16:35:10][log.py][line:68][ERROR] 产生错误于：【 kkzcc9457ss@126.com】发送失败
[2020-01-14 16:35:10][log.py][line:68][ERROR] (535, b'Error: authentication failed')
[2020-01-14 16:35:10][log.py][line:58][INFO] 
[2020-01-14 16:35:13][log.py][line:58][INFO] 发送账号【ypovw7381jq@126.com】正在发送
[2020-01-14 16:35:13][log.py][line:58][INFO] 接受序号【41】【27217255@qq.com】发送成功
[2020-01-14 16:35:13][log.py][line:58][INFO] 
[2020-01-14 16:37:45][log.py][line:68][ERROR] 产生错误于：【fnw371@163.com】发送失败
[2020-01-14 16:37:45][log.py][line:68][ERROR] (550, b'User has no permission')
[2020-01-14 16:37:45][log.py][line:58][INFO] 
[2020-01-14 16:37:47][log.py][line:68][ERROR] 产生错误于：【scf635@163.com】发送失败
[2020-01-14 16:37:47][log.py][line:68][ERROR] (550, b'User has no permission')
[2020-01-14 16:37:47][log.py][line:58][INFO] 
[2020-01-14 16:37:49][log.py][line:58][INFO] 发送账号【ss13126325@sina.com】正在发送
[2020-01-14 16:37:49][log.py][line:58][INFO] 接受序号【42】【06806270@qq.com】发送成功
[2020-01-14 16:37:49][log.py][line:58][INFO] 
[2020-01-14 16:40:22][log.py][line:58][INFO] 发送账号【b8y5yb@163.com】正在发送
[2020-01-14 16:40:22][log.py][line:58][INFO] 接受序号【43】【36587541@qq.com】发送成功
[2020-01-14 16:40:22][log.py][line:58][INFO] 
[2020-01-14 16:42:54][log.py][line:58][INFO] 发送账号【ss13126325@sina.com】正在发送
[2020-01-14 16:42:54][log.py][line:58][INFO] 接受序号【44】【16170687@qq.com】发送成功
[2020-01-14 16:42:54][log.py][line:58][INFO] 
[2020-01-14 16:45:26][log.py][line:58][INFO] 发送账号【fpgic3160mg@126.com】正在发送
[2020-01-14 16:45:26][log.py][line:58][INFO] 接受序号【45】【47239362@qq.com】发送成功
[2020-01-14 16:45:26][log.py][line:58][INFO] 
[2020-01-14 16:47:58][log.py][line:58][INFO] 发送账号【qvgxd8220mk@126.com】正在发送
[2020-01-14 16:47:58][log.py][line:58][INFO] 接受序号【46】【86181687@qq.com】发送成功
[2020-01-14 16:47:58][log.py][line:58][INFO] 
[2020-01-14 16:50:29][log.py][line:58][INFO] 发送账号【pmncd4350xu@126.com】正在发送
[2020-01-14 16:50:29][log.py][line:58][INFO] 接受序号【47】【38016355@qq.com】发送成功
[2020-01-14 16:50:29][log.py][line:58][INFO] 
[2020-01-14 16:53:01][log.py][line:58][INFO] 发送账号【ss13126325@sina.com】正在发送
[2020-01-14 16:53:01][log.py][line:58][INFO] 接受序号【48】【68149647@qq.com】发送成功
[2020-01-14 16:53:01][log.py][line:58][INFO] 
[2020-01-14 16:55:34][log.py][line:58][INFO] 发送账号【e5l8g7@163.com】正在发送
[2020-01-14 16:55:34][log.py][line:58][INFO] 接受序号【49】【43530300@qq.com】发送成功
[2020-01-14 16:55:34][log.py][line:58][INFO] 
[2020-01-14 16:58:05][log.py][line:68][ERROR] 产生错误于：【vtv424@163.com】发送失败
[2020-01-14 16:58:05][log.py][line:68][ERROR] (550, b'User has no permission')
[2020-01-14 16:58:05][log.py][line:58][INFO] 
[2020-01-14 16:58:08][log.py][line:58][INFO] 发送账号【icvma2101ry@126.com】正在发送
[2020-01-14 16:58:08][log.py][line:58][INFO] 接受序号【50】【41567092@qq.com】发送成功
[2020-01-14 16:58:08][log.py][line:58][INFO] 
[2020-01-14 17:00:39][log.py][line:58][INFO] 发送账号【oprul919zy@126.com】正在发送
[2020-01-14 17:00:39][log.py][line:58][INFO] 接受序号【51】【29745383@qq.com】发送成功
[2020-01-14 17:00:39][log.py][line:58][INFO] 
[2020-01-14 17:03:11][log.py][line:68][ERROR] 产生错误于：【n0c125@163.com】发送失败
[2020-01-14 17:03:11][log.py][line:68][ERROR] (550, b'User has no permission')
[2020-01-14 17:03:11][log.py][line:58][INFO] 
[2020-01-14 17:03:12][log.py][line:58][INFO] 发送账号【e4m6s2@163.com】正在发送
[2020-01-14 17:03:12][log.py][line:58][INFO] 接受序号【52】【88206630@qq.com】发送成功
[2020-01-14 17:03:12][log.py][line:58][INFO] 
[2020-01-14 17:05:43][log.py][line:68][ERROR] 产生错误于：【 lvfja7380rj@126.com】发送失败
[2020-01-14 17:05:43][log.py][line:68][ERROR] (535, b'Error: authentication failed')
[2020-01-14 17:05:43][log.py][line:58][INFO] 
[2020-01-14 17:05:45][log.py][line:58][INFO] 发送账号【ngm67a@163.com】正在发送
[2020-01-14 17:05:45][log.py][line:58][INFO] 接受序号【53】【47494158@qq.com】发送成功
[2020-01-14 17:05:45][log.py][line:58][INFO] 
[2020-01-14 17:08:17][log.py][line:58][INFO] 发送账号【ss13126325@sina.com】正在发送
[2020-01-14 17:08:17][log.py][line:58][INFO] 接受序号【54】【41721767@qq.com】发送成功
[2020-01-14 17:08:17][log.py][line:58][INFO] 
[2020-01-14 17:10:48][log.py][line:58][INFO] 发送账号【bgk90z@163.com】正在发送
[2020-01-14 17:10:48][log.py][line:58][INFO] 接受序号【55】【58581979@qq.com】发送成功
[2020-01-14 17:10:48][log.py][line:58][INFO] 
[2020-01-14 17:13:22][log.py][line:58][INFO] 发送账号【ubnpx7683xu@126.com】正在发送
[2020-01-14 17:13:22][log.py][line:58][INFO] 接受序号【56】【10273031@qq.com】发送成功
[2020-01-14 17:13:22][log.py][line:58][INFO] 
[2020-01-14 17:15:54][log.py][line:68][ERROR] 产生错误于：【h18t4u@163.com】发送失败
[2020-01-14 17:15:54][log.py][line:68][ERROR] (550, b'User has no permission')
[2020-01-14 17:15:54][log.py][line:58][INFO] 
[2020-01-14 17:15:55][log.py][line:58][INFO] 发送账号【u1v00h@163.com】正在发送
[2020-01-14 17:15:55][log.py][line:58][INFO] 接受序号【57】【40548971@qq.com】发送成功
[2020-01-14 17:15:55][log.py][line:58][INFO] 
[2020-01-14 17:18:27][log.py][line:58][INFO] 发送账号【ddonv7986lj@126.com】正在发送
[2020-01-14 17:18:27][log.py][line:58][INFO] 接受序号【58】【76257097@qq.com】发送成功
[2020-01-14 17:18:27][log.py][line:58][INFO] 
[2020-01-14 17:20:58][log.py][line:68][ERROR] 产生错误于：【uzt515@163.com】发送失败
[2020-01-14 17:20:58][log.py][line:68][ERROR] (550, b'User has no permission')
[2020-01-14 17:20:58][log.py][line:58][INFO] 
[2020-01-14 17:21:00][log.py][line:58][INFO] 发送账号【luwwd0361rs@126.com】正在发送
[2020-01-14 17:21:00][log.py][line:58][INFO] 接受序号【59】【50725118@qq.com】发送成功
[2020-01-14 17:21:00][log.py][line:58][INFO] 
[2020-01-14 17:23:32][log.py][line:58][INFO] 发送账号【fdxdi580so@126.com】正在发送
[2020-01-14 17:23:32][log.py][line:58][INFO] 接受序号【60】【29010193@qq.com】发送成功
[2020-01-14 17:23:32][log.py][line:58][INFO] 
[2020-01-14 17:26:04][log.py][line:58][INFO] 发送账号【ss13126325@sina.com】正在发送
[2020-01-14 17:26:04][log.py][line:58][INFO] 接受序号【61】【99109057@qq.com】发送成功
[2020-01-14 17:26:04][log.py][line:58][INFO] 
[2020-01-14 17:28:37][log.py][line:68][ERROR] 产生错误于：【une291@163.com】发送失败
[2020-01-14 17:28:37][log.py][line:68][ERROR] (550, b'User has no permission')
[2020-01-14 17:28:37][log.py][line:58][INFO] 
[2020-01-14 17:28:40][log.py][line:58][INFO] 发送账号【dtf1gb@163.com】正在发送
[2020-01-14 17:28:40][log.py][line:58][INFO] 接受序号【62】【50858330@qq.com】发送成功
[2020-01-14 17:28:40][log.py][line:58][INFO] 
[2020-01-14 17:31:11][log.py][line:68][ERROR] 产生错误于：【 xlk578@163.com】发送失败
[2020-01-14 17:31:11][log.py][line:68][ERROR] (535, b'Error: authentication failed')
[2020-01-14 17:31:11][log.py][line:58][INFO] 
[2020-01-14 17:31:13][log.py][line:68][ERROR] 产生错误于：【n0c125@163.com】发送失败
[2020-01-14 17:31:13][log.py][line:68][ERROR] (550, b'User has no permission')
[2020-01-14 17:31:13][log.py][line:58][INFO] 
[2020-01-14 17:31:14][log.py][line:68][ERROR] 产生错误于：【jo91888@126.com】发送失败
[2020-01-14 17:31:14][log.py][line:68][ERROR] (550, b'\xd3\xc3\xbb\xa7\xce\xde\xc8\xa8\xb5\xc7\xc2\xbd')
[2020-01-14 17:31:14][log.py][line:58][INFO] 
[2020-01-14 17:31:15][log.py][line:58][INFO] 发送账号【gncjm0521ou@126.com】正在发送
[2020-01-14 17:31:15][log.py][line:58][INFO] 接受序号【63】【59748629@qq.com】发送成功
[2020-01-14 17:31:15][log.py][line:58][INFO] 
[2020-01-14 17:33:47][log.py][line:68][ERROR] 产生错误于：【yni631@163.com】发送失败
[2020-01-14 17:33:47][log.py][line:68][ERROR] (550, b'User has no permission')
[2020-01-14 17:33:47][log.py][line:58][INFO] 
[2020-01-14 17:33:50][log.py][line:58][INFO] 发送账号【okrbh0857wq@126.com】正在发送
[2020-01-14 17:33:50][log.py][line:58][INFO] 接受序号【64】【74303994@qq.com】发送成功
[2020-01-14 17:33:50][log.py][line:58][INFO] 
[2020-01-14 17:36:22][log.py][line:58][INFO] 发送账号【ss13126325@sina.com】正在发送
[2020-01-14 17:36:22][log.py][line:58][INFO] 接受序号【65】【77673589@qq.com】发送成功
[2020-01-14 17:36:22][log.py][line:58][INFO] 
[2020-01-14 17:38:54][log.py][line:68][ERROR] 产生错误于：【tel955@163.com】发送失败
[2020-01-14 17:38:54][log.py][line:68][ERROR] (550, b'User has no permission')
[2020-01-14 17:38:54][log.py][line:58][INFO] 
[2020-01-14 17:38:56][log.py][line:58][INFO] 发送账号【fdn975333@126.com】正在发送
[2020-01-14 17:38:56][log.py][line:58][INFO] 接受序号【66】【79615940@qq.com】发送成功
[2020-01-14 17:38:56][log.py][line:58][INFO] 
[2020-01-14 17:41:28][log.py][line:58][INFO] 发送账号【ss13126325@sina.com】正在发送
[2020-01-14 17:41:28][log.py][line:58][INFO] 接受序号【67】【37679082@qq.com】发送成功
[2020-01-14 17:41:28][log.py][line:58][INFO] 
[2020-01-14 17:44:01][log.py][line:58][INFO] 发送账号【ss13126325@sina.com】正在发送
[2020-01-14 17:44:01][log.py][line:58][INFO] 接受序号【68】【29316901@qq.com】发送成功
[2020-01-14 17:44:01][log.py][line:58][INFO] 
[2020-01-14 17:46:33][log.py][line:58][INFO] 发送账号【hljeq7441qu@126.com】正在发送
[2020-01-14 17:46:33][log.py][line:58][INFO] 接受序号【69】【69345525@qq.com】发送成功
[2020-01-14 17:46:33][log.py][line:58][INFO] 
[2020-01-14 17:49:05][log.py][line:58][INFO] 发送账号【aqjyn4615jq@126.com】正在发送
[2020-01-14 17:49:05][log.py][line:58][INFO] 接受序号【70】【97249114@qq.com】发送成功
[2020-01-14 17:49:05][log.py][line:58][INFO] 
[2020-01-14 17:51:37][log.py][line:58][INFO] 发送账号【ibqhn0074ck@126.com】正在发送
[2020-01-14 17:51:37][log.py][line:58][INFO] 接受序号【71】【24460230@qq.com】发送成功
[2020-01-14 17:51:37][log.py][line:58][INFO] 
[2020-01-14 17:54:08][log.py][line:68][ERROR] 产生错误于：【fyu452@163.com】发送失败
[2020-01-14 17:54:08][log.py][line:68][ERROR] (550, b'User has no permission')
[2020-01-14 17:54:08][log.py][line:58][INFO] 
[2020-01-14 17:54:10][log.py][line:68][ERROR] 产生错误于：【vsv224@163.com】发送失败
[2020-01-14 17:54:10][log.py][line:68][ERROR] (550, b'User has no permission')
[2020-01-14 17:54:10][log.py][line:58][INFO] 
[2020-01-14 17:54:11][log.py][line:68][ERROR] 产生错误于：【tel955@163.com】发送失败
[2020-01-14 17:54:11][log.py][line:68][ERROR] (550, b'User has no permission')
[2020-01-14 17:54:11][log.py][line:58][INFO] 
[2020-01-14 17:54:13][log.py][line:58][INFO] 发送账号【ybk8zf@163.com】正在发送
[2020-01-14 17:54:13][log.py][line:58][INFO] 接受序号【72】【61534138@qq.com】发送成功
[2020-01-14 17:54:13][log.py][line:58][INFO] 
[2020-01-14 17:56:45][log.py][line:58][INFO] 发送账号【e2e8xt@163.com】正在发送
[2020-01-14 17:56:45][log.py][line:58][INFO] 接受序号【73】【73826349@qq.com】发送成功
[2020-01-14 17:56:45][log.py][line:58][INFO] 
[2020-01-14 17:59:17][log.py][line:58][INFO] 发送账号【ss13126325@sina.com】正在发送
[2020-01-14 17:59:17][log.py][line:58][INFO] 接受序号【74】【25779466@qq.com】发送成功
[2020-01-14 17:59:17][log.py][line:58][INFO] 
[2020-01-14 18:01:48][log.py][line:68][ERROR] 产生错误于：【aeo770@163.com】发送失败
[2020-01-14 18:01:48][log.py][line:68][ERROR] (550, b'User has no permission')
[2020-01-14 18:01:48][log.py][line:58][INFO] 
[2020-01-14 18:01:49][log.py][line:68][ERROR] 产生错误于：【oke20z@163.com】发送失败
[2020-01-14 18:01:49][log.py][line:68][ERROR] (550, b'User has no permission')
[2020-01-14 18:01:49][log.py][line:58][INFO] 
[2020-01-14 18:01:51][log.py][line:58][INFO] 发送账号【ss13126325@sina.com】正在发送
[2020-01-14 18:01:51][log.py][line:58][INFO] 接受序号【75】【05164665@qq.com】发送成功
[2020-01-14 18:01:51][log.py][line:58][INFO] 
[2020-01-14 18:04:23][log.py][line:68][ERROR] 产生错误于：【 kbjdk516rd@126.com】发送失败
[2020-01-14 18:04:23][log.py][line:68][ERROR] (535, b'Error: authentication failed')
[2020-01-14 18:04:23][log.py][line:58][INFO] 
[2020-01-14 18:04:25][log.py][line:68][ERROR] 产生错误于：【wM31ZA@163.com】发送失败
[2020-01-14 18:04:25][log.py][line:68][ERROR] (550, b'User has no permission')
[2020-01-14 18:04:25][log.py][line:58][INFO] 
[2020-01-14 18:04:26][log.py][line:68][ERROR] 产生错误于：【mkm635@163.com】发送失败
[2020-01-14 18:04:26][log.py][line:68][ERROR] (550, b'User has no permission')
[2020-01-14 18:04:26][log.py][line:58][INFO] 
[2020-01-14 18:04:28][log.py][line:58][INFO] 发送账号【bwg6qg@163.com】正在发送
[2020-01-14 18:04:28][log.py][line:58][INFO] 接受序号【76】【06934498@qq.com】发送成功
[2020-01-14 18:04:28][log.py][line:58][INFO] 
[2020-01-14 18:06:59][log.py][line:68][ERROR] 产生错误于：【bkt980@163.com】发送失败
[2020-01-14 18:06:59][log.py][line:68][ERROR] (550, b'User has no permission')
[2020-01-14 18:06:59][log.py][line:58][INFO] 
[2020-01-14 18:07:01][log.py][line:58][INFO] 发送账号【qkclo2932ex@126.com】正在发送
[2020-01-14 18:07:01][log.py][line:58][INFO] 接受序号【77】【48609170@qq.com】发送成功
[2020-01-14 18:07:01][log.py][line:58][INFO] 
[2020-01-14 18:09:33][log.py][line:58][INFO] 发送账号【xkq9kr@163.com】正在发送
[2020-01-14 18:09:33][log.py][line:58][INFO] 接受序号【78】【71656102@qq.com】发送成功
[2020-01-14 18:09:33][log.py][line:58][INFO] 
[2020-01-14 18:12:25][log.py][line:68][ERROR] 产生错误于：【z5i0pf@163.com】发送失败
[2020-01-14 18:12:25][log.py][line:68][ERROR] [Errno 11001] getaddrinfo failed
[2020-01-14 18:12:25][log.py][line:58][INFO] 
[2020-01-14 18:12:26][log.py][line:68][ERROR] 产生错误于：【zr96np@163.com】发送失败
[2020-01-14 18:12:26][log.py][line:68][ERROR] [Errno 11001] getaddrinfo failed
[2020-01-14 18:12:26][log.py][line:58][INFO] 
[2020-01-14 18:12:27][log.py][line:68][ERROR] 产生错误于：【ss13126325@sina.com】发送失败
[2020-01-14 18:12:27][log.py][line:68][ERROR] [Errno 11001] getaddrinfo failed
[2020-01-14 18:12:27][log.py][line:58][INFO] 
[2020-01-14 18:17:16][log.py][line:68][ERROR] 产生错误于：【zkqqc3785cd@126.com】发送失败
[2020-01-14 18:17:16][log.py][line:68][ERROR] [WinError 10060] 由于连接方在一段时间后没有正确答复或连接的主机没有反应，连接尝试失败。
[2020-01-14 18:17:16][log.py][line:58][INFO] 
[2020-01-14 18:17:28][log.py][line:68][ERROR] 产生错误于：【ykx7z4@163.com】发送失败
[2020-01-14 18:17:28][log.py][line:68][ERROR] [Errno 11001] getaddrinfo failed
[2020-01-14 18:17:28][log.py][line:58][INFO] 
[2020-01-14 18:17:40][log.py][line:68][ERROR] 产生错误于：【lho651@163.com】发送失败
[2020-01-14 18:17:40][log.py][line:68][ERROR] [Errno 11001] getaddrinfo failed
[2020-01-14 18:17:40][log.py][line:58][INFO] 
[2020-01-14 18:19:48][log.py][line:68][ERROR] 产生错误于：【ykgfw0041ei@126.com】发送失败
[2020-01-14 18:19:48][log.py][line:68][ERROR] [WinError 10060] 由于连接方在一段时间后没有正确答复或连接的主机没有反应，连接尝试失败。
[2020-01-14 18:19:48][log.py][line:58][INFO] 
[2020-01-14 18:21:24][log.py][line:68][ERROR] 产生错误于：【cjaes3532xx@126.com】发送失败
[2020-01-14 18:21:24][log.py][line:68][ERROR] [WinError 10060] 由于连接方在一段时间后没有正确答复或连接的主机没有反应，连接尝试失败。
[2020-01-14 18:21:24][log.py][line:58][INFO] 
[2020-01-14 18:21:36][log.py][line:68][ERROR] 产生错误于：【ezn804@163.com】发送失败
[2020-01-14 18:21:36][log.py][line:68][ERROR] [Errno 11001] getaddrinfo failed
[2020-01-14 18:21:36][log.py][line:58][INFO] 
[2020-01-14 18:21:48][log.py][line:68][ERROR] 产生错误于：【fyk7sc@163.com】发送失败
[2020-01-14 18:21:48][log.py][line:68][ERROR] [Errno 11001] getaddrinfo failed
[2020-01-14 18:21:48][log.py][line:58][INFO] 
[2020-01-14 18:21:48][log.py][line:68][ERROR] 产生错误于：【mhw83q@163.com】发送失败
[2020-01-14 18:21:48][log.py][line:68][ERROR] [Errno 11001] getaddrinfo failed
[2020-01-14 18:21:48][log.py][line:58][INFO] 
[2020-01-14 18:21:49][log.py][line:68][ERROR] 产生错误于：【nxg16d@163.com】发送失败
[2020-01-14 18:21:49][log.py][line:68][ERROR] [Errno 11001] getaddrinfo failed
[2020-01-14 18:21:49][log.py][line:58][INFO] 
[2020-01-14 18:21:50][log.py][line:68][ERROR] 产生错误于：【uyo935@163.com】发送失败
[2020-01-14 18:21:50][log.py][line:68][ERROR] [Errno 11001] getaddrinfo failed
[2020-01-14 18:21:50][log.py][line:58][INFO] 
[2020-01-14 18:23:15][log.py][line:68][ERROR] 产生错误于：【 orfqg9173qg@126.com】发送失败
[2020-01-14 18:23:15][log.py][line:68][ERROR] [WinError 10060] 由于连接方在一段时间后没有正确答复或连接的主机没有反应，连接尝试失败。
[2020-01-14 18:23:15][log.py][line:58][INFO] 
[2020-01-14 18:23:27][log.py][line:68][ERROR] 产生错误于：【qvv251@163.com】发送失败
[2020-01-14 18:23:27][log.py][line:68][ERROR] [Errno 11001] getaddrinfo failed
[2020-01-14 18:23:27][log.py][line:58][INFO] 
[2020-01-14 18:23:28][log.py][line:68][ERROR] 产生错误于：【cik8kr@163.com】发送失败
[2020-01-14 18:23:28][log.py][line:68][ERROR] [Errno 11001] getaddrinfo failed
[2020-01-14 18:23:28][log.py][line:58][INFO] 
[2020-01-14 18:24:53][log.py][line:68][ERROR] 产生错误于：【ooawa0847wu@126.com】发送失败
[2020-01-14 18:24:53][log.py][line:68][ERROR] [WinError 10060] 由于连接方在一段时间后没有正确答复或连接的主机没有反应，连接尝试失败。
[2020-01-14 18:24:53][log.py][line:58][INFO] 
[2020-01-14 18:25:05][log.py][line:68][ERROR] 产生错误于：【pmncd4350xu@126.com】发送失败
[2020-01-14 18:25:05][log.py][line:68][ERROR] [Errno 11001] getaddrinfo failed
[2020-01-14 18:25:05][log.py][line:58][INFO] 
[2020-01-14 18:25:05][log.py][line:68][ERROR] 产生错误于：【zuk597@163.com】发送失败
[2020-01-14 18:25:05][log.py][line:68][ERROR] [Errno 11001] getaddrinfo failed
[2020-01-14 18:25:05][log.py][line:58][INFO] 
[2020-01-14 18:25:06][log.py][line:68][ERROR] 产生错误于：【ss13126325@sina.com】发送失败
[2020-01-14 18:25:06][log.py][line:68][ERROR] [Errno 11001] getaddrinfo failed
[2020-01-14 18:25:06][log.py][line:58][INFO] 
[2020-01-14 18:25:07][log.py][line:68][ERROR] 产生错误于：【ss13126325@sina.com】发送失败
[2020-01-14 18:25:07][log.py][line:68][ERROR] [Errno 11001] getaddrinfo failed
[2020-01-14 18:25:07][log.py][line:58][INFO] 
[2020-01-14 18:25:08][log.py][line:68][ERROR] 产生错误于：【wtm232@163.com】发送失败
[2020-01-14 18:25:08][log.py][line:68][ERROR] [Errno 11001] getaddrinfo failed
[2020-01-14 18:25:08][log.py][line:58][INFO] 
[2020-01-14 18:25:20][log.py][line:68][ERROR] 产生错误于：【kws738@163.com】发送失败
[2020-01-14 18:25:20][log.py][line:68][ERROR] [Errno 11001] getaddrinfo failed
[2020-01-14 18:25:20][log.py][line:58][INFO] 
[2020-01-14 18:25:21][log.py][line:68][ERROR] 产生错误于：【ulxob8071wu@126.com】发送失败
[2020-01-14 18:25:21][log.py][line:68][ERROR] [Errno 11001] getaddrinfo failed
[2020-01-14 18:25:21][log.py][line:58][INFO] 
[2020-01-14 18:25:43][log.py][line:68][ERROR] 产生错误于：【ss13126325@sina.com】发送失败
[2020-01-14 18:25:43][log.py][line:68][ERROR] [Errno 11001] getaddrinfo failed
[2020-01-14 18:25:43][log.py][line:58][INFO] 
[2020-01-14 18:26:06][log.py][line:68][ERROR] 产生错误于：【mmtby7664qa@126.com】发送失败
[2020-01-14 18:26:06][log.py][line:68][ERROR] [Errno 11001] getaddrinfo failed
[2020-01-14 18:26:06][log.py][line:58][INFO] 
[2020-01-14 18:26:29][log.py][line:68][ERROR] 产生错误于：【mwk2h8@163.com】发送失败
[2020-01-14 18:26:29][log.py][line:68][ERROR] [Errno 11001] getaddrinfo failed
[2020-01-14 18:26:29][log.py][line:58][INFO] 
[2020-01-14 18:26:51][log.py][line:68][ERROR] 产生错误于：【 ilrjj8054ok@126.com】发送失败
[2020-01-14 18:26:51][log.py][line:68][ERROR] [Errno 11001] getaddrinfo failed
[2020-01-14 18:26:51][log.py][line:58][INFO] 
[2020-01-14 18:27:14][log.py][line:68][ERROR] 产生错误于：【ngm67a@163.com】发送失败
[2020-01-14 18:27:14][log.py][line:68][ERROR] [Errno 11001] getaddrinfo failed
[2020-01-14 18:27:14][log.py][line:58][INFO] 
[2020-01-14 18:27:37][log.py][line:68][ERROR] 产生错误于：【kgmir9@163.com】发送失败
[2020-01-14 18:27:37][log.py][line:68][ERROR] [Errno 11001] getaddrinfo failed
[2020-01-14 18:27:37][log.py][line:58][INFO] 
[2020-01-14 18:27:49][log.py][line:68][ERROR] 产生错误于：【ss13126325@sina.com】发送失败
[2020-01-14 18:27:49][log.py][line:68][ERROR] [Errno 11001] getaddrinfo failed
[2020-01-14 18:27:49][log.py][line:58][INFO] 
[2020-01-14 18:27:50][log.py][line:68][ERROR] 产生错误于：【l0e7m1@163.com】发送失败
[2020-01-14 18:27:50][log.py][line:68][ERROR] [Errno 11001] getaddrinfo failed
[2020-01-14 18:27:50][log.py][line:58][INFO] 
[2020-01-14 18:27:51][log.py][line:68][ERROR] 产生错误于：【vev591@163.com】发送失败
[2020-01-14 18:27:51][log.py][line:68][ERROR] [Errno 11001] getaddrinfo failed
[2020-01-14 18:27:51][log.py][line:58][INFO] 
[2020-01-14 18:27:52][log.py][line:68][ERROR] 产生错误于：【ss13126325@sina.com】发送失败
[2020-01-14 18:27:52][log.py][line:68][ERROR] [Errno 11001] getaddrinfo failed
[2020-01-14 18:27:52][log.py][line:58][INFO] 
[2020-01-14 18:27:53][log.py][line:68][ERROR] 产生错误于：【ss13126325@sina.com】发送失败
[2020-01-14 18:27:53][log.py][line:68][ERROR] [Errno 11001] getaddrinfo failed
[2020-01-14 18:27:53][log.py][line:58][INFO] 
[2020-01-14 18:28:04][log.py][line:68][ERROR] 产生错误于：【dos297@163.com】发送失败
[2020-01-14 18:28:04][log.py][line:68][ERROR] [Errno 11001] getaddrinfo failed
[2020-01-14 18:28:04][log.py][line:58][INFO] 
[2020-01-14 18:28:05][log.py][line:68][ERROR] 产生错误于：【rpu837@163.com】发送失败
[2020-01-14 18:28:05][log.py][line:68][ERROR] [Errno 11001] getaddrinfo failed
[2020-01-14 18:28:05][log.py][line:58][INFO] 
[2020-01-14 18:28:16][log.py][line:68][ERROR] 产生错误于：【erwvh3464cg@126.com】发送失败
[2020-01-14 18:28:16][log.py][line:68][ERROR] [Errno 11001] getaddrinfo failed
[2020-01-14 18:28:16][log.py][line:58][INFO] 
[2020-01-14 18:28:17][log.py][line:68][ERROR] 产生错误于：【k929l7@163.com】发送失败
[2020-01-14 18:28:17][log.py][line:68][ERROR] [Errno 11001] getaddrinfo failed
[2020-01-14 18:28:17][log.py][line:58][INFO] 
[2020-01-14 18:28:29][log.py][line:68][ERROR] 产生错误于：【kll406@163.com】发送失败
[2020-01-14 18:28:29][log.py][line:68][ERROR] [Errno 11001] getaddrinfo failed
[2020-01-14 18:28:29][log.py][line:58][INFO] 
[2020-01-14 18:28:30][log.py][line:68][ERROR] 产生错误于：【mwk2h8@163.com】发送失败
[2020-01-14 18:28:30][log.py][line:68][ERROR] [Errno 11001] getaddrinfo failed
[2020-01-14 18:28:30][log.py][line:58][INFO] 
[2020-01-14 18:28:31][log.py][line:68][ERROR] 产生错误于：【aic785@163.com】发送失败
[2020-01-14 18:28:31][log.py][line:68][ERROR] [Errno 11001] getaddrinfo failed
[2020-01-14 18:28:31][log.py][line:58][INFO] 
[2020-01-14 18:28:32][log.py][line:68][ERROR] 产生错误于：【baafu2440na@126.com】发送失败
[2020-01-14 18:28:32][log.py][line:68][ERROR] [Errno 11001] getaddrinfo failed
[2020-01-14 18:28:32][log.py][line:58][INFO] 
[2020-01-14 18:28:32][log.py][line:68][ERROR] 产生错误于：【pfp726@163.com】发送失败
[2020-01-14 18:28:32][log.py][line:68][ERROR] [Errno 11001] getaddrinfo failed
[2020-01-14 18:28:32][log.py][line:58][INFO] 
[2020-01-14 18:28:41][log.py][line:68][ERROR] 产生错误于：【ine278@163.com】发送失败
[2020-01-14 18:28:41][log.py][line:68][ERROR] [Errno 11001] getaddrinfo failed
[2020-01-14 18:28:41][log.py][line:58][INFO] 
[2020-01-14 18:28:42][log.py][line:68][ERROR] 产生错误于：【l4o45l@163.com】发送失败
[2020-01-14 18:28:42][log.py][line:68][ERROR] [Errno 11001] getaddrinfo failed
[2020-01-14 18:28:42][log.py][line:58][INFO] 
[2020-01-14 18:28:43][log.py][line:68][ERROR] 产生错误于：【bnq677@163.com】发送失败
[2020-01-14 18:28:43][log.py][line:68][ERROR] [Errno 11001] getaddrinfo failed
[2020-01-14 18:28:43][log.py][line:58][INFO] 
[2020-01-14 18:28:43][log.py][line:68][ERROR] 'ascii' codec can't encode character '\xa0' in position 0: ordinal not in range(128)
[2020-01-14 18:28:43][log.py][line:58][INFO] 
[2020-01-14 18:28:43][log.py][line:68][ERROR] 产生错误于：【dux277@163.com】发送失败
[2020-01-14 18:28:43][log.py][line:68][ERROR] [Errno 11001] getaddrinfo failed
[2020-01-14 18:28:43][log.py][line:58][INFO] 
[2020-01-14 18:28:44][log.py][line:68][ERROR] 产生错误于：【pxfvk8551vy@126.com】发送失败
[2020-01-14 18:28:44][log.py][line:68][ERROR] [Errno 11001] getaddrinfo failed
[2020-01-14 18:28:44][log.py][line:58][INFO] 
[2020-01-14 18:28:45][log.py][line:68][ERROR] 产生错误于：【 v9m55j@163.com】发送失败
[2020-01-14 18:28:45][log.py][line:68][ERROR] [Errno 11001] getaddrinfo failed
[2020-01-14 18:28:45][log.py][line:58][INFO] 
[2020-01-14 18:28:53][log.py][line:68][ERROR] 产生错误于：【kdf644@163.com】发送失败
[2020-01-14 18:28:53][log.py][line:68][ERROR] [Errno 11001] getaddrinfo failed
[2020-01-14 18:28:53][log.py][line:58][INFO] 
[2020-01-14 18:28:54][log.py][line:68][ERROR] 产生错误于：【ss13126325@sina.com】发送失败
[2020-01-14 18:28:54][log.py][line:68][ERROR] [Errno 11001] getaddrinfo failed
[2020-01-14 18:28:54][log.py][line:58][INFO] 
[2020-01-14 18:28:54][log.py][line:68][ERROR] 产生错误于：【ss13126325@sina.com】发送失败
[2020-01-14 18:28:54][log.py][line:68][ERROR] [Errno 11001] getaddrinfo failed
[2020-01-14 18:28:54][log.py][line:58][INFO] 
[2020-01-14 18:28:55][log.py][line:68][ERROR] 产生错误于：【xalox8658ej@126.com】发送失败
[2020-01-14 18:28:55][log.py][line:68][ERROR] [Errno 11001] getaddrinfo failed
[2020-01-14 18:28:55][log.py][line:58][INFO] 
[2020-01-14 18:28:56][log.py][line:68][ERROR] 产生错误于：【dvn933@163.com】发送失败
[2020-01-14 18:28:56][log.py][line:68][ERROR] [Errno 11001] getaddrinfo failed
[2020-01-14 18:28:56][log.py][line:58][INFO] 
[2020-01-14 18:28:57][log.py][line:68][ERROR] 产生错误于：【ss13126325@sina.com】发送失败
[2020-01-14 18:28:57][log.py][line:68][ERROR] [Errno 11001] getaddrinfo failed
[2020-01-14 18:28:57][log.py][line:58][INFO] 
[2020-01-14 18:29:05][log.py][line:68][ERROR] 产生错误于：【akqxz8192nn@126.com】发送失败
[2020-01-14 18:29:05][log.py][line:68][ERROR] [Errno 11001] getaddrinfo failed
[2020-01-14 18:29:05][log.py][line:58][INFO] 
[2020-01-14 18:29:06][log.py][line:68][ERROR] 产生错误于：【ss13126325@sina.com】发送失败
[2020-01-14 18:29:06][log.py][line:68][ERROR] [Errno 11001] getaddrinfo failed
[2020-01-14 18:29:06][log.py][line:58][INFO] 
[2020-01-14 18:29:06][log.py][line:68][ERROR] 产生错误于：【 lsr935@163.com】发送失败
[2020-01-14 18:29:06][log.py][line:68][ERROR] [Errno 11001] getaddrinfo failed
[2020-01-14 18:29:06][log.py][line:58][INFO] 
[2020-01-14 18:29:07][log.py][line:68][ERROR] 产生错误于：【izmfs6121qf@126.com】发送失败
[2020-01-14 18:29:07][log.py][line:68][ERROR] [Errno 11001] getaddrinfo failed
[2020-01-14 18:29:07][log.py][line:58][INFO] 
[2020-01-14 18:29:08][log.py][line:68][ERROR] 产生错误于：【jn2i9y@163.com】发送失败
[2020-01-14 18:29:08][log.py][line:68][ERROR] [Errno 11001] getaddrinfo failed
[2020-01-14 18:29:08][log.py][line:58][INFO] 
[2020-01-14 18:29:09][log.py][line:68][ERROR] 产生错误于：【ss13126325@sina.com】发送失败
[2020-01-14 18:29:09][log.py][line:68][ERROR] [Errno 11001] getaddrinfo failed
[2020-01-14 18:29:09][log.py][line:58][INFO] 
[2020-01-14 18:29:28][log.py][line:68][ERROR] 产生错误于：【ulxob8071wu@126.com】发送失败
[2020-01-14 18:29:28][log.py][line:68][ERROR] [Errno 11001] getaddrinfo failed
[2020-01-14 18:29:28][log.py][line:58][INFO] 
[2020-01-14 18:29:40][log.py][line:68][ERROR] 产生错误于：【lnf5ns@163.com】发送失败
[2020-01-14 18:29:40][log.py][line:68][ERROR] [Errno 11001] getaddrinfo failed
[2020-01-14 18:29:40][log.py][line:58][INFO] 
[2020-01-14 18:29:40][log.py][line:68][ERROR] 产生错误于：【ss13126325@sina.com】发送失败
[2020-01-14 18:29:40][log.py][line:68][ERROR] [Errno 11001] getaddrinfo failed
[2020-01-14 18:29:40][log.py][line:58][INFO] 
[2020-01-14 18:29:41][log.py][line:68][ERROR] 产生错误于：【gncjm0521ou@126.com】发送失败
[2020-01-14 18:29:41][log.py][line:68][ERROR] [Errno 11001] getaddrinfo failed
[2020-01-14 18:29:41][log.py][line:58][INFO] 
[2020-01-14 18:29:42][log.py][line:68][ERROR] 产生错误于：【ss13126325@sina.com】发送失败
[2020-01-14 18:29:42][log.py][line:68][ERROR] [Errno 11001] getaddrinfo failed
[2020-01-14 18:29:42][log.py][line:58][INFO] 
[2020-01-14 18:29:43][log.py][line:68][ERROR] 产生错误于：【tmt754@163.com】发送失败
[2020-01-14 18:29:43][log.py][line:68][ERROR] [Errno 11001] getaddrinfo failed
[2020-01-14 18:29:43][log.py][line:58][INFO] 
[2020-01-14 18:29:44][log.py][line:68][ERROR] 产生错误于：【a7e737@163.com】发送失败
[2020-01-14 18:29:44][log.py][line:68][ERROR] [Errno 11001] getaddrinfo failed
[2020-01-14 18:29:44][log.py][line:58][INFO] 
[2020-01-14 18:29:51][log.py][line:68][ERROR] 产生错误于：【bismw8916cu@126.com】发送失败
[2020-01-14 18:29:51][log.py][line:68][ERROR] [Errno 11001] getaddrinfo failed
[2020-01-14 18:29:51][log.py][line:58][INFO] 
[2020-01-14 18:29:52][log.py][line:68][ERROR] 产生错误于：【sif185@163.com】发送失败
[2020-01-14 18:29:52][log.py][line:68][ERROR] [Errno 11001] getaddrinfo failed
[2020-01-14 18:29:52][log.py][line:58][INFO] 
[2020-01-14 18:29:53][log.py][line:68][ERROR] 产生错误于：【ggo4ia@163.com】发送失败
[2020-01-14 18:29:53][log.py][line:68][ERROR] [Errno 11001] getaddrinfo failed
[2020-01-14 18:29:53][log.py][line:58][INFO] 
[2020-01-14 18:29:54][log.py][line:68][ERROR] 产生错误于：【ss13126325@sina.com】发送失败
[2020-01-14 18:29:54][log.py][line:68][ERROR] [Errno 11001] getaddrinfo failed
[2020-01-14 18:29:54][log.py][line:58][INFO] 
[2020-01-14 18:29:55][log.py][line:68][ERROR] 产生错误于：【iqwxy0401fm@126.com】发送失败
[2020-01-14 18:29:55][log.py][line:68][ERROR] [Errno 11001] getaddrinfo failed
[2020-01-14 18:29:55][log.py][line:58][INFO] 
[2020-01-14 18:30:02][log.py][line:68][ERROR] 产生错误于：【ezjsh7913yb@126.com】发送失败
[2020-01-14 18:30:02][log.py][line:68][ERROR] [Errno 11001] getaddrinfo failed
[2020-01-14 18:30:02][log.py][line:58][INFO] 
[2020-01-14 18:30:03][log.py][line:68][ERROR] 产生错误于：【ss13126325@sina.com】发送失败
[2020-01-14 18:30:03][log.py][line:68][ERROR] [Errno 11001] getaddrinfo failed
[2020-01-14 18:30:03][log.py][line:58][INFO] 
[2020-01-14 18:30:04][log.py][line:68][ERROR] 产生错误于：【yvdks4381tk@126.com】发送失败
[2020-01-14 18:30:04][log.py][line:68][ERROR] [Errno 11001] getaddrinfo failed
[2020-01-14 18:30:04][log.py][line:58][INFO] 
[2020-01-14 18:30:05][log.py][line:68][ERROR] 产生错误于：【ss13126325@sina.com】发送失败
[2020-01-14 18:30:05][log.py][line:68][ERROR] [Errno 11001] getaddrinfo failed
[2020-01-14 18:30:05][log.py][line:58][INFO] 
[2020-01-14 18:30:06][log.py][line:68][ERROR] 产生错误于：【5lgh7@163.com】发送失败
[2020-01-14 18:30:06][log.py][line:68][ERROR] [Errno 11001] getaddrinfo failed
[2020-01-14 18:30:06][log.py][line:58][INFO] 
[2020-01-14 18:30:07][log.py][line:68][ERROR] 产生错误于：【bgqgt772jn@126.com】发送失败
[2020-01-14 18:30:07][log.py][line:68][ERROR] [Errno 11001] getaddrinfo failed
[2020-01-14 18:30:07][log.py][line:58][INFO] 
[2020-01-14 18:30:19][log.py][line:68][ERROR] 产生错误于：【u9b46h@163.com】发送失败
[2020-01-14 18:30:19][log.py][line:68][ERROR] [Errno 11001] getaddrinfo failed
[2020-01-14 18:30:19][log.py][line:58][INFO] 
[2020-01-14 18:30:19][log.py][line:68][ERROR] 产生错误于：【sds468@163.com】发送失败
[2020-01-14 18:30:19][log.py][line:68][ERROR] [Errno 11001] getaddrinfo failed
[2020-01-14 18:30:19][log.py][line:58][INFO] 
[2020-01-14 18:30:30][log.py][line:68][ERROR] 产生错误于：【jla771@163.com】发送失败
[2020-01-14 18:30:30][log.py][line:68][ERROR] [Errno 11001] getaddrinfo failed
[2020-01-14 18:30:30][log.py][line:58][INFO] 
[2020-01-14 18:30:42][log.py][line:68][ERROR] 产生错误于：【ss13126325@sina.com】发送失败
[2020-01-14 18:30:42][log.py][line:68][ERROR] [Errno 11001] getaddrinfo failed
[2020-01-14 18:30:42][log.py][line:58][INFO] 
[2020-01-14 18:30:54][log.py][line:68][ERROR] 产生错误于：【sbr297@163.com】发送失败
[2020-01-14 18:30:54][log.py][line:68][ERROR] [Errno 11001] getaddrinfo failed
[2020-01-14 18:30:54][log.py][line:58][INFO] 
[2020-01-14 18:31:06][log.py][line:68][ERROR] 产生错误于：【 i6m5nh@163.com】发送失败
[2020-01-14 18:31:06][log.py][line:68][ERROR] [Errno 11001] getaddrinfo failed
[2020-01-14 18:31:06][log.py][line:58][INFO] 
[2020-01-14 18:31:07][log.py][line:68][ERROR] 产生错误于：【pwknx029uq@126.com】发送失败
[2020-01-14 18:31:07][log.py][line:68][ERROR] [Errno 11001] getaddrinfo failed
[2020-01-14 18:31:07][log.py][line:58][INFO] 
[2020-01-14 18:31:08][log.py][line:68][ERROR] 产生错误于：【vkg9a6@163.com】发送失败
[2020-01-14 18:31:08][log.py][line:68][ERROR] [Errno 11001] getaddrinfo failed
[2020-01-14 18:31:08][log.py][line:58][INFO] 
[2020-01-14 18:31:09][log.py][line:68][ERROR] 产生错误于：【txn956@163.com】发送失败
[2020-01-14 18:31:09][log.py][line:68][ERROR] [Errno 11001] getaddrinfo failed
[2020-01-14 18:31:09][log.py][line:58][INFO] 
[2020-01-14 18:31:09][log.py][line:68][ERROR] 产生错误于：【ss13126325@sina.com】发送失败
[2020-01-14 18:31:09][log.py][line:68][ERROR] [Errno 11001] getaddrinfo failed
[2020-01-14 18:31:09][log.py][line:58][INFO] 
[2020-01-14 18:31:21][log.py][line:68][ERROR] 产生错误于：【gte255@163.com】发送失败
[2020-01-14 18:31:21][log.py][line:68][ERROR] [Errno 11001] getaddrinfo failed
[2020-01-14 18:31:21][log.py][line:58][INFO] 
[2020-01-14 18:31:22][log.py][line:68][ERROR] 产生错误于：【 v9m55j@163.com】发送失败
[2020-01-14 18:31:22][log.py][line:68][ERROR] [Errno 11001] getaddrinfo failed
[2020-01-14 18:31:22][log.py][line:58][INFO] 
[2020-01-14 18:31:33][log.py][line:68][ERROR] 产生错误于：【 sjw10q@163.com】发送失败
[2020-01-14 18:31:33][log.py][line:68][ERROR] [Errno 11001] getaddrinfo failed
[2020-01-14 18:31:33][log.py][line:58][INFO] 
[2020-01-14 18:31:34][log.py][line:68][ERROR] 产生错误于：【cke783@163.com】发送失败
[2020-01-14 18:31:34][log.py][line:68][ERROR] [Errno 11001] getaddrinfo failed
[2020-01-14 18:31:34][log.py][line:58][INFO] 
[2020-01-14 18:31:44][log.py][line:68][ERROR] 产生错误于：【gdw197@163.com】发送失败
[2020-01-14 18:31:44][log.py][line:68][ERROR] [Errno 11001] getaddrinfo failed
[2020-01-14 18:31:44][log.py][line:58][INFO] 
[2020-01-14 18:31:45][log.py][line:68][ERROR] 产生错误于：【txn956@163.com】发送失败
[2020-01-14 18:31:45][log.py][line:68][ERROR] [Errno 11001] getaddrinfo failed
[2020-01-14 18:31:45][log.py][line:58][INFO] 
[2020-01-14 18:31:46][log.py][line:68][ERROR] 产生错误于：【ss13126325@sina.com】发送失败
[2020-01-14 18:31:46][log.py][line:68][ERROR] [Errno 11001] getaddrinfo failed
[2020-01-14 18:31:46][log.py][line:58][INFO] 
[2020-01-14 18:31:47][log.py][line:68][ERROR] 产生错误于：【uys951@163.com】发送失败
[2020-01-14 18:31:47][log.py][line:68][ERROR] [Errno 11001] getaddrinfo failed
[2020-01-14 18:31:47][log.py][line:58][INFO] 
[2020-01-14 18:31:48][log.py][line:68][ERROR] 产生错误于：【ss13126325@sina.com】发送失败
[2020-01-14 18:31:48][log.py][line:68][ERROR] [Errno 11001] getaddrinfo failed
[2020-01-14 18:31:48][log.py][line:58][INFO] 
[2020-01-14 18:31:48][log.py][line:68][ERROR] 产生错误于：【w8i46z@163.com】发送失败
[2020-01-14 18:31:48][log.py][line:68][ERROR] [Errno 11001] getaddrinfo failed
[2020-01-14 18:31:48][log.py][line:58][INFO] 
[2020-01-14 18:32:00][log.py][line:68][ERROR] 产生错误于：【xb198y@163.com】发送失败
[2020-01-14 18:32:00][log.py][line:68][ERROR] [Errno 11001] getaddrinfo failed
[2020-01-14 18:32:00][log.py][line:58][INFO] 
[2020-01-14 18:32:01][log.py][line:68][ERROR] 产生错误于：【gzs476@163.com】发送失败
[2020-01-14 18:32:01][log.py][line:68][ERROR] [Errno 11001] getaddrinfo failed
[2020-01-14 18:32:01][log.py][line:58][INFO] 
[2020-01-14 18:32:12][log.py][line:68][ERROR] 产生错误于：【o6n553@163.com】发送失败
[2020-01-14 18:32:12][log.py][line:68][ERROR] [Errno 11001] getaddrinfo failed
[2020-01-14 18:32:12][log.py][line:58][INFO] 
[2020-01-14 18:32:13][log.py][line:68][ERROR] 产生错误于：【kzjyv5776mb@126.com】发送失败
[2020-01-14 18:32:13][log.py][line:68][ERROR] [Errno 11001] getaddrinfo failed
[2020-01-14 18:32:13][log.py][line:58][INFO] 
[2020-01-14 18:32:14][log.py][line:68][ERROR] 产生错误于：【ze73ym@163.com】发送失败
[2020-01-14 18:32:14][log.py][line:68][ERROR] [Errno 11001] getaddrinfo failed
[2020-01-14 18:32:14][log.py][line:58][INFO] 
[2020-01-14 18:32:15][log.py][line:68][ERROR] 产生错误于：【xdgeu1726fj@126.com】发送失败
[2020-01-14 18:32:15][log.py][line:68][ERROR] [Errno 11001] getaddrinfo failed
[2020-01-14 18:32:15][log.py][line:58][INFO] 
[2020-01-14 18:32:16][log.py][line:68][ERROR] 产生错误于：【upt816@163.com】发送失败
[2020-01-14 18:32:16][log.py][line:68][ERROR] [Errno 11001] getaddrinfo failed
[2020-01-14 18:32:16][log.py][line:58][INFO] 
[2020-01-14 18:32:16][log.py][line:68][ERROR] 产生错误于：【ungmv1@163.com】发送失败
[2020-01-14 18:32:16][log.py][line:68][ERROR] [Errno 11001] getaddrinfo failed
[2020-01-14 18:32:16][log.py][line:58][INFO] 
[2020-01-14 18:32:24][log.py][line:68][ERROR] 产生错误于：【vjh695@163.com】发送失败
[2020-01-14 18:32:24][log.py][line:68][ERROR] [Errno 11001] getaddrinfo failed
[2020-01-14 18:32:24][log.py][line:58][INFO] 
[2020-01-14 18:32:25][log.py][line:68][ERROR] 产生错误于：【kbnes7713ui@126.com】发送失败
[2020-01-14 18:32:25][log.py][line:68][ERROR] [Errno 11001] getaddrinfo failed
[2020-01-14 18:32:25][log.py][line:58][INFO] 
[2020-01-14 18:32:26][log.py][line:68][ERROR] 产生错误于：【srpom5910bc@126.com】发送失败
[2020-01-14 18:32:26][log.py][line:68][ERROR] [Errno 11001] getaddrinfo failed
[2020-01-14 18:32:26][log.py][line:58][INFO] 
[2020-01-14 18:32:27][log.py][line:68][ERROR] 产生错误于：【cik8kr@163.com】发送失败
[2020-01-14 18:32:27][log.py][line:68][ERROR] [Errno 11001] getaddrinfo failed
[2020-01-14 18:32:27][log.py][line:58][INFO] 
[2020-01-14 18:32:27][log.py][line:68][ERROR] 产生错误于：【jqktu438rl@126.com】发送失败
[2020-01-14 18:32:27][log.py][line:68][ERROR] [Errno 11001] getaddrinfo failed
[2020-01-14 18:32:27][log.py][line:58][INFO] 
[2020-01-14 18:32:35][log.py][line:68][ERROR] 产生错误于：【y75lo4@163.com】发送失败
[2020-01-14 18:32:35][log.py][line:68][ERROR] [Errno 11001] getaddrinfo failed
[2020-01-14 18:32:35][log.py][line:58][INFO] 
[2020-01-14 18:32:36][log.py][line:68][ERROR] 产生错误于：【h18t4u@163.com】发送失败
[2020-01-14 18:32:36][log.py][line:68][ERROR] [Errno 11001] getaddrinfo failed
[2020-01-14 18:32:36][log.py][line:58][INFO] 
[2020-01-14 18:32:37][log.py][line:68][ERROR] 产生错误于：【pcxmd3459aa@126.com】发送失败
[2020-01-14 18:32:37][log.py][line:68][ERROR] [Errno 11001] getaddrinfo failed
[2020-01-14 18:32:37][log.py][line:58][INFO] 
[2020-01-14 18:32:38][log.py][line:68][ERROR] 产生错误于：【ze73ym@163.com】发送失败
[2020-01-14 18:32:38][log.py][line:68][ERROR] [Errno 11001] getaddrinfo failed
[2020-01-14 18:32:38][log.py][line:58][INFO] 
[2020-01-14 18:32:38][log.py][line:68][ERROR] 产生错误于：【o4654j@163.com】发送失败
[2020-01-14 18:32:38][log.py][line:68][ERROR] [Errno 11001] getaddrinfo failed
[2020-01-14 18:32:38][log.py][line:58][INFO] 
[2020-01-14 18:32:39][log.py][line:68][ERROR] 产生错误于：【xkq9kr@163.com】发送失败
[2020-01-14 18:32:39][log.py][line:68][ERROR] [Errno 11001] getaddrinfo failed
[2020-01-14 18:32:39][log.py][line:58][INFO] 
[2020-01-14 18:32:47][log.py][line:68][ERROR] 产生错误于：【sif185@163.com】发送失败
[2020-01-14 18:32:47][log.py][line:68][ERROR] [Errno 11001] getaddrinfo failed
[2020-01-14 18:32:47][log.py][line:58][INFO] 
[2020-01-14 18:32:48][log.py][line:68][ERROR] 产生错误于：【gvw28q@163.com】发送失败
[2020-01-14 18:32:48][log.py][line:68][ERROR] [Errno 11001] getaddrinfo failed
[2020-01-14 18:32:48][log.py][line:58][INFO] 
[2020-01-14 18:32:49][log.py][line:68][ERROR] 产生错误于：【 fho1xe@163.com】发送失败
[2020-01-14 18:32:49][log.py][line:68][ERROR] [Errno 11001] getaddrinfo failed
[2020-01-14 18:32:49][log.py][line:58][INFO] 
[2020-01-14 18:32:50][log.py][line:68][ERROR] 产生错误于：【ss13126325@sina.com】发送失败
[2020-01-14 18:32:50][log.py][line:68][ERROR] [Errno 11001] getaddrinfo failed
[2020-01-14 18:32:50][log.py][line:58][INFO] 
[2020-01-14 18:32:50][log.py][line:68][ERROR] 产生错误于：【j614it@163.com】发送失败
[2020-01-14 18:32:50][log.py][line:68][ERROR] [Errno 11001] getaddrinfo failed
[2020-01-14 18:32:50][log.py][line:58][INFO] 
[2020-01-14 18:32:51][log.py][line:68][ERROR] 产生错误于：【kov393@163.com】发送失败
[2020-01-14 18:32:51][log.py][line:68][ERROR] [Errno 11001] getaddrinfo failed
[2020-01-14 18:32:51][log.py][line:58][INFO] 
[2020-01-14 18:32:59][log.py][line:68][ERROR] 产生错误于：【gvi127@163.com】发送失败
[2020-01-14 18:32:59][log.py][line:68][ERROR] [Errno 11001] getaddrinfo failed
[2020-01-14 18:32:59][log.py][line:58][INFO] 
[2020-01-14 18:33:00][log.py][line:68][ERROR] 产生错误于：【5lgh7@163.com】发送失败
[2020-01-14 18:33:00][log.py][line:68][ERROR] [Errno 11001] getaddrinfo failed
[2020-01-14 18:33:00][log.py][line:58][INFO] 
[2020-01-14 18:33:01][log.py][line:68][ERROR] 产生错误于：【 jtj3l5@163.com】发送失败
[2020-01-14 18:33:01][log.py][line:68][ERROR] [Errno 11001] getaddrinfo failed
[2020-01-14 18:33:01][log.py][line:58][INFO] 
[2020-01-14 18:33:01][log.py][line:68][ERROR] 产生错误于：【ss13126325@sina.com】发送失败
[2020-01-14 18:33:01][log.py][line:68][ERROR] [Errno 11001] getaddrinfo failed
[2020-01-14 18:33:01][log.py][line:58][INFO] 
[2020-01-14 18:33:02][log.py][line:68][ERROR] 产生错误于：【mzr183@163.com】发送失败
[2020-01-14 18:33:02][log.py][line:68][ERROR] [Errno 11001] getaddrinfo failed
[2020-01-14 18:33:02][log.py][line:58][INFO] 
[2020-01-14 18:33:03][log.py][line:68][ERROR] 产生错误于：【msq781@163.com】发送失败
[2020-01-14 18:33:03][log.py][line:68][ERROR] [Errno 11001] getaddrinfo failed
[2020-01-14 18:33:03][log.py][line:58][INFO] 
[2020-01-14 18:33:11][log.py][line:68][ERROR] 产生错误于：【faeov5634yr@126.com】发送失败
[2020-01-14 18:33:11][log.py][line:68][ERROR] [Errno 11001] getaddrinfo failed
[2020-01-14 18:33:11][log.py][line:58][INFO] 
[2020-01-14 18:33:12][log.py][line:68][ERROR] 产生错误于：【ss13126325@sina.com】发送失败
[2020-01-14 18:33:12][log.py][line:68][ERROR] [Errno 11001] getaddrinfo failed
[2020-01-14 18:33:12][log.py][line:58][INFO] 
[2020-01-14 18:33:12][log.py][line:68][ERROR] 产生错误于：【ss13126325@sina.com】发送失败
[2020-01-14 18:33:12][log.py][line:68][ERROR] [Errno 11001] getaddrinfo failed
[2020-01-14 18:33:12][log.py][line:58][INFO] 
[2020-01-14 18:33:13][log.py][line:68][ERROR] 产生错误于：【ai83th@163.com】发送失败
[2020-01-14 18:33:13][log.py][line:68][ERROR] [Errno 11001] getaddrinfo failed
[2020-01-14 18:33:13][log.py][line:58][INFO] 
[2020-01-14 18:33:14][log.py][line:68][ERROR] 产生错误于：【oes1vm@163.com】发送失败
[2020-01-14 18:33:14][log.py][line:68][ERROR] [Errno 11001] getaddrinfo failed
[2020-01-14 18:33:14][log.py][line:58][INFO] 
[2020-01-14 18:33:22][log.py][line:68][ERROR] 产生错误于：【ezrnb8626bt@126.com】发送失败
[2020-01-14 18:33:22][log.py][line:68][ERROR] [Errno 11001] getaddrinfo failed
[2020-01-14 18:33:22][log.py][line:58][INFO] 
[2020-01-14 18:33:23][log.py][line:68][ERROR] 产生错误于：【s1obo0@163.com】发送失败
[2020-01-14 18:33:23][log.py][line:68][ERROR] [Errno 11001] getaddrinfo failed
[2020-01-14 18:33:23][log.py][line:58][INFO] 
[2020-01-14 18:33:23][log.py][line:68][ERROR] 产生错误于：【zkrhc8724ye@126.com】发送失败
[2020-01-14 18:33:23][log.py][line:68][ERROR] [Errno 11001] getaddrinfo failed
[2020-01-14 18:33:23][log.py][line:58][INFO] 
[2020-01-14 18:33:24][log.py][line:68][ERROR] 产生错误于：【zl100165440@126.com】发送失败
[2020-01-14 18:33:24][log.py][line:68][ERROR] [Errno 11001] getaddrinfo failed
[2020-01-14 18:33:24][log.py][line:58][INFO] 
[2020-01-14 18:33:25][log.py][line:68][ERROR] 产生错误于：【kws738@163.com】发送失败
[2020-01-14 18:33:25][log.py][line:68][ERROR] [Errno 11001] getaddrinfo failed
[2020-01-14 18:33:25][log.py][line:58][INFO] 
[2020-01-14 18:33:26][log.py][line:68][ERROR] 产生错误于：【upt816@163.com】发送失败
[2020-01-14 18:33:26][log.py][line:68][ERROR] [Errno 11001] getaddrinfo failed
[2020-01-14 18:33:26][log.py][line:58][INFO] 
[2020-01-14 18:33:38][log.py][line:68][ERROR] 产生错误于：【ajryw3189yl@126.com】发送失败
[2020-01-14 18:33:38][log.py][line:68][ERROR] [Errno 11001] getaddrinfo failed
[2020-01-14 18:33:38][log.py][line:58][INFO] 
[2020-01-14 18:33:39][log.py][line:68][ERROR] 产生错误于：【mli413@163.com】发送失败
[2020-01-14 18:33:39][log.py][line:68][ERROR] [Errno 11001] getaddrinfo failed
[2020-01-14 18:33:39][log.py][line:58][INFO] 
[2020-01-14 18:33:50][log.py][line:68][ERROR] 产生错误于：【jeuap0817dy@126.com】发送失败
[2020-01-14 18:33:50][log.py][line:68][ERROR] [Errno 11001] getaddrinfo failed
[2020-01-14 18:33:50][log.py][line:58][INFO] 
[2020-01-14 18:34:02][log.py][line:68][ERROR] 产生错误于：【ss13126325@sina.com】发送失败
[2020-01-14 18:34:02][log.py][line:68][ERROR] [Errno 11001] getaddrinfo failed
[2020-01-14 18:34:02][log.py][line:58][INFO] 
[2020-01-14 18:34:02][log.py][line:68][ERROR] 产生错误于：【z463av@163.com】发送失败
[2020-01-14 18:34:02][log.py][line:68][ERROR] [Errno 11001] getaddrinfo failed
[2020-01-14 18:34:02][log.py][line:58][INFO] 
[2020-01-14 18:34:03][log.py][line:68][ERROR] 产生错误于：【bismw8916cu@126.com】发送失败
[2020-01-14 18:34:03][log.py][line:68][ERROR] [Errno 11001] getaddrinfo failed
[2020-01-14 18:34:03][log.py][line:58][INFO] 
[2020-01-14 18:34:04][log.py][line:68][ERROR] 产生错误于：【urt6ca@163.com】发送失败
[2020-01-14 18:34:04][log.py][line:68][ERROR] [Errno 11001] getaddrinfo failed
[2020-01-14 18:34:04][log.py][line:58][INFO] 
[2020-01-14 18:34:05][log.py][line:68][ERROR] 产生错误于：【jeuap0817dy@126.com】发送失败
[2020-01-14 18:34:05][log.py][line:68][ERROR] [Errno 11001] getaddrinfo failed
[2020-01-14 18:34:05][log.py][line:58][INFO] 
[2020-01-14 18:34:06][log.py][line:68][ERROR] 产生错误于：【ss13126325@sina.com】发送失败
[2020-01-14 18:34:06][log.py][line:68][ERROR] [Errno 11001] getaddrinfo failed
[2020-01-14 18:34:06][log.py][line:58][INFO] 
[2020-01-14 18:34:14][log.py][line:68][ERROR] 产生错误于：【vlq205@163.com】发送失败
[2020-01-14 18:34:14][log.py][line:68][ERROR] [Errno 11001] getaddrinfo failed
[2020-01-14 18:34:14][log.py][line:58][INFO] 
[2020-01-14 18:34:14][log.py][line:68][ERROR] 产生错误于：【umr637@163.com】发送失败
[2020-01-14 18:34:14][log.py][line:68][ERROR] [Errno 11001] getaddrinfo failed
[2020-01-14 18:34:14][log.py][line:58][INFO] 
[2020-01-14 18:34:15][log.py][line:68][ERROR] 产生错误于：【uudjk2596th@126.com】发送失败
[2020-01-14 18:34:15][log.py][line:68][ERROR] [Errno 11001] getaddrinfo failed
[2020-01-14 18:34:15][log.py][line:58][INFO] 
[2020-01-14 18:34:16][log.py][line:68][ERROR] 产生错误于：【icvma2101ry@126.com】发送失败
[2020-01-14 18:34:16][log.py][line:68][ERROR] [Errno 11001] getaddrinfo failed
[2020-01-14 18:34:16][log.py][line:58][INFO] 
[2020-01-14 18:34:17][log.py][line:68][ERROR] 产生错误于：【tlp8v5@163.com】发送失败
[2020-01-14 18:34:17][log.py][line:68][ERROR] [Errno 11001] getaddrinfo failed
[2020-01-14 18:34:17][log.py][line:58][INFO] 
[2020-01-14 18:34:18][log.py][line:68][ERROR] 产生错误于：【u9b46h@163.com】发送失败
[2020-01-14 18:34:18][log.py][line:68][ERROR] [Errno 11001] getaddrinfo failed
[2020-01-14 18:34:18][log.py][line:58][INFO] 
[2020-01-14 18:34:25][log.py][line:68][ERROR] 产生错误于：【nkv283@163.com】发送失败
[2020-01-14 18:34:25][log.py][line:68][ERROR] [Errno 11001] getaddrinfo failed
[2020-01-14 18:34:25][log.py][line:58][INFO] 
[2020-01-14 18:34:26][log.py][line:68][ERROR] 产生错误于：【idd504@163.com】发送失败
[2020-01-14 18:34:26][log.py][line:68][ERROR] [Errno 11001] getaddrinfo failed
[2020-01-14 18:34:26][log.py][line:58][INFO] 
[2020-01-14 18:34:27][log.py][line:68][ERROR] 产生错误于：【qbb075@163.com】发送失败
[2020-01-14 18:34:27][log.py][line:68][ERROR] [Errno 11001] getaddrinfo failed
[2020-01-14 18:34:27][log.py][line:58][INFO] 
[2020-01-14 18:34:28][log.py][line:68][ERROR] 产生错误于：【qse512@163.com】发送失败
[2020-01-14 18:34:28][log.py][line:68][ERROR] [Errno 11001] getaddrinfo failed
[2020-01-14 18:34:28][log.py][line:58][INFO] 
[2020-01-14 18:34:29][log.py][line:68][ERROR] 产生错误于：【ss13126325@sina.com】发送失败
[2020-01-14 18:34:29][log.py][line:68][ERROR] [Errno 11001] getaddrinfo failed
[2020-01-14 18:34:29][log.py][line:58][INFO] 
[2020-01-14 18:34:30][log.py][line:68][ERROR] 产生错误于：【f3r7r4@163.com】发送失败
[2020-01-14 18:34:30][log.py][line:68][ERROR] [Errno 11001] getaddrinfo failed
[2020-01-14 18:34:30][log.py][line:58][INFO] 
[2020-01-14 18:34:37][log.py][line:68][ERROR] 产生错误于：【vep676@163.com】发送失败
[2020-01-14 18:34:37][log.py][line:68][ERROR] [Errno 11001] getaddrinfo failed
[2020-01-14 18:34:37][log.py][line:58][INFO] 
[2020-01-14 18:34:38][log.py][line:68][ERROR] 产生错误于：【ss13126325@sina.com】发送失败
[2020-01-14 18:34:38][log.py][line:68][ERROR] [Errno 11001] getaddrinfo failed
[2020-01-14 18:34:38][log.py][line:58][INFO] 
[2020-01-14 18:34:39][log.py][line:68][ERROR] 产生错误于：【gv576m@163.com】发送失败
[2020-01-14 18:34:39][log.py][line:68][ERROR] [Errno 11001] getaddrinfo failed
[2020-01-14 18:34:39][log.py][line:58][INFO] 
[2020-01-14 18:34:40][log.py][line:68][ERROR] 产生错误于：【hkbcy4146ff@126.com】发送失败
[2020-01-14 18:34:40][log.py][line:68][ERROR] [Errno 11001] getaddrinfo failed
[2020-01-14 18:34:40][log.py][line:58][INFO] 
[2020-01-14 18:34:41][log.py][line:68][ERROR] 产生错误于：【x247o6@163.com】发送失败
[2020-01-14 18:34:41][log.py][line:68][ERROR] [Errno 11001] getaddrinfo failed
[2020-01-14 18:34:41][log.py][line:58][INFO] 
[2020-01-14 18:34:42][log.py][line:68][ERROR] 产生错误于：【bvash2526ve@126.com】发送失败
[2020-01-14 18:34:42][log.py][line:68][ERROR] [Errno 11001] getaddrinfo failed
[2020-01-14 18:34:42][log.py][line:58][INFO] 
[2020-01-14 18:34:49][log.py][line:68][ERROR] 产生错误于：【ss13126325@sina.com】发送失败
[2020-01-14 18:34:49][log.py][line:68][ERROR] [Errno 11001] getaddrinfo failed
[2020-01-14 18:34:49][log.py][line:58][INFO] 
[2020-01-14 18:34:50][log.py][line:68][ERROR] 产生错误于：【qtw738@163.com】发送失败
[2020-01-14 18:34:50][log.py][line:68][ERROR] [Errno 11001] getaddrinfo failed
[2020-01-14 18:34:50][log.py][line:58][INFO] 
[2020-01-14 18:34:51][log.py][line:68][ERROR] 产生错误于：【 kdy619@163.com】发送失败
[2020-01-14 18:34:51][log.py][line:68][ERROR] [Errno 11001] getaddrinfo failed
[2020-01-14 18:34:51][log.py][line:58][INFO] 
[2020-01-14 18:34:52][log.py][line:68][ERROR] 产生错误于：【qqwpi6563ue@126.com】发送失败
[2020-01-14 18:34:52][log.py][line:68][ERROR] [Errno 11001] getaddrinfo failed
[2020-01-14 18:34:52][log.py][line:58][INFO] 
[2020-01-14 18:34:53][log.py][line:68][ERROR] 产生错误于：【dmqzy9892sd@126.com】发送失败
[2020-01-14 18:34:53][log.py][line:68][ERROR] [Errno 11001] getaddrinfo failed
[2020-01-14 18:34:53][log.py][line:58][INFO] 
[2020-01-14 18:34:53][log.py][line:68][ERROR] 产生错误于：【ss13126325@sina.com】发送失败
[2020-01-14 18:34:53][log.py][line:68][ERROR] [Errno 11001] getaddrinfo failed
[2020-01-14 18:34:53][log.py][line:58][INFO] 
[2020-01-14 18:35:01][log.py][line:68][ERROR] 产生错误于：【wpg8cy@163.com】发送失败
[2020-01-14 18:35:01][log.py][line:68][ERROR] [Errno 11001] getaddrinfo failed
[2020-01-14 18:35:01][log.py][line:58][INFO] 
[2020-01-14 18:35:02][log.py][line:68][ERROR] 产生错误于：【ss13126325@sina.com】发送失败
[2020-01-14 18:35:02][log.py][line:68][ERROR] [Errno 11001] getaddrinfo failed
[2020-01-14 18:35:02][log.py][line:58][INFO] 
[2020-01-14 18:35:03][log.py][line:68][ERROR] 产生错误于：【sef618@163.com】发送失败
[2020-01-14 18:35:03][log.py][line:68][ERROR] [Errno 11001] getaddrinfo failed
[2020-01-14 18:35:03][log.py][line:58][INFO] 
[2020-01-14 18:35:04][log.py][line:68][ERROR] 产生错误于：【pxkzr1127ao@126.com】发送失败
[2020-01-14 18:35:04][log.py][line:68][ERROR] [Errno 11001] getaddrinfo failed
[2020-01-14 18:35:04][log.py][line:58][INFO] 
[2020-01-14 18:35:04][log.py][line:68][ERROR] 产生错误于：【sk248028226@126.com】发送失败
[2020-01-14 18:35:04][log.py][line:68][ERROR] [Errno 11001] getaddrinfo failed
[2020-01-14 18:35:04][log.py][line:58][INFO] 
[2020-01-14 18:35:05][log.py][line:68][ERROR] 产生错误于：【aijre4607vw@126.com】发送失败
[2020-01-14 18:35:05][log.py][line:68][ERROR] [Errno 11001] getaddrinfo failed
[2020-01-14 18:35:05][log.py][line:58][INFO] 
[2020-01-14 18:35:13][log.py][line:68][ERROR] 产生错误于：【 og370l@163.com】发送失败
[2020-01-14 18:35:13][log.py][line:68][ERROR] [Errno 11001] getaddrinfo failed
[2020-01-14 18:35:13][log.py][line:58][INFO] 
[2020-01-14 18:35:14][log.py][line:68][ERROR] 产生错误于：【pcxmd3459aa@126.com】发送失败
[2020-01-14 18:35:14][log.py][line:68][ERROR] [Errno 11001] getaddrinfo failed
[2020-01-14 18:35:14][log.py][line:58][INFO] 
[2020-01-14 18:35:15][log.py][line:68][ERROR] 产生错误于：【d348w8@163.com】发送失败
[2020-01-14 18:35:15][log.py][line:68][ERROR] [Errno 11001] getaddrinfo failed
[2020-01-14 18:35:15][log.py][line:58][INFO] 
[2020-01-14 18:35:15][log.py][line:68][ERROR] 产生错误于：【cf704g@163.com】发送失败
[2020-01-14 18:35:15][log.py][line:68][ERROR] [Errno 11001] getaddrinfo failed
[2020-01-14 18:35:15][log.py][line:58][INFO] 
[2020-01-14 18:35:16][log.py][line:68][ERROR] 产生错误于：【ss13126325@sina.com】发送失败
[2020-01-14 18:35:16][log.py][line:68][ERROR] [Errno 11001] getaddrinfo failed
[2020-01-14 18:35:16][log.py][line:58][INFO] 
[2020-01-14 18:35:17][log.py][line:68][ERROR] 产生错误于：【lzm460@163.com】发送失败
[2020-01-14 18:35:17][log.py][line:68][ERROR] [Errno 11001] getaddrinfo failed
[2020-01-14 18:35:17][log.py][line:58][INFO] 
[2020-01-14 18:35:25][log.py][line:68][ERROR] 产生错误于：【y24eiv@163.com】发送失败
[2020-01-14 18:35:25][log.py][line:68][ERROR] [Errno 11001] getaddrinfo failed
[2020-01-14 18:35:25][log.py][line:58][INFO] 
[2020-01-14 18:35:26][log.py][line:68][ERROR] 产生错误于：【ss13126325@sina.com】发送失败
[2020-01-14 18:35:26][log.py][line:68][ERROR] [Errno 11001] getaddrinfo failed
[2020-01-14 18:35:26][log.py][line:58][INFO] 
[2020-01-14 18:35:26][log.py][line:68][ERROR] 产生错误于：【 a1395l@163.com】发送失败
[2020-01-14 18:35:26][log.py][line:68][ERROR] [Errno 11001] getaddrinfo failed
[2020-01-14 18:35:26][log.py][line:58][INFO] 
[2020-01-14 18:35:27][log.py][line:68][ERROR] 产生错误于：【cbeae2373dj@126.com】发送失败
[2020-01-14 18:35:27][log.py][line:68][ERROR] [Errno 11001] getaddrinfo failed
[2020-01-14 18:35:27][log.py][line:58][INFO] 
[2020-01-14 18:35:28][log.py][line:68][ERROR] 产生错误于：【knh5l2@163.com】发送失败
[2020-01-14 18:35:28][log.py][line:68][ERROR] [Errno 11001] getaddrinfo failed
[2020-01-14 18:35:28][log.py][line:58][INFO] 
[2020-01-14 18:35:40][log.py][line:68][ERROR] 产生错误于：【ss13126325@sina.com】发送失败
[2020-01-14 18:35:40][log.py][line:68][ERROR] [Errno 11001] getaddrinfo failed
[2020-01-14 18:35:40][log.py][line:58][INFO] 
[2020-01-14 18:35:41][log.py][line:68][ERROR] 产生错误于：【l0308q@163.com】发送失败
[2020-01-14 18:35:41][log.py][line:68][ERROR] [Errno 11001] getaddrinfo failed
[2020-01-14 18:35:41][log.py][line:58][INFO] 
[2020-01-14 18:35:52][log.py][line:68][ERROR] 产生错误于：【ss13126325@sina.com】发送失败
[2020-01-14 18:35:52][log.py][line:68][ERROR] [Errno 11001] getaddrinfo failed
[2020-01-14 18:35:52][log.py][line:58][INFO] 
[2020-01-14 18:36:04][log.py][line:68][ERROR] 产生错误于：【sl99u6@163.com】发送失败
[2020-01-14 18:36:04][log.py][line:68][ERROR] [Errno 11001] getaddrinfo failed
[2020-01-14 18:36:04][log.py][line:58][INFO] 
[2020-01-14 18:36:05][log.py][line:68][ERROR] 产生错误于：【rzuyp158zf@126.com】发送失败
[2020-01-14 18:36:05][log.py][line:68][ERROR] [Errno 11001] getaddrinfo failed
[2020-01-14 18:36:05][log.py][line:58][INFO] 
[2020-01-14 18:36:05][log.py][line:68][ERROR] 产生错误于：【xhpky2744ej@126.com】发送失败
[2020-01-14 18:36:05][log.py][line:68][ERROR] [Errno 11001] getaddrinfo failed
[2020-01-14 18:36:05][log.py][line:58][INFO] 
[2020-01-14 18:36:06][log.py][line:68][ERROR] 产生错误于：【k610px@163.com】发送失败
[2020-01-14 18:36:06][log.py][line:68][ERROR] [Errno 11001] getaddrinfo failed
[2020-01-14 18:36:06][log.py][line:58][INFO] 
[2020-01-14 18:36:07][log.py][line:68][ERROR] 产生错误于：【ss13126325@sina.com】发送失败
[2020-01-14 18:36:07][log.py][line:68][ERROR] [Errno 11001] getaddrinfo failed
[2020-01-14 18:36:07][log.py][line:58][INFO] 
[2020-01-14 18:36:08][log.py][line:68][ERROR] 产生错误于：【ss13126325@sina.com】发送失败
[2020-01-14 18:36:08][log.py][line:68][ERROR] [Errno 11001] getaddrinfo failed
[2020-01-14 18:36:08][log.py][line:58][INFO] 
[2020-01-14 18:36:16][log.py][line:68][ERROR] 产生错误于：【pig33z@163.com】发送失败
[2020-01-14 18:36:16][log.py][line:68][ERROR] [Errno 11001] getaddrinfo failed
[2020-01-14 18:36:16][log.py][line:58][INFO] 
[2020-01-14 18:36:28][log.py][line:68][ERROR] 产生错误于：【gdw197@163.com】发送失败
[2020-01-14 18:36:28][log.py][line:68][ERROR] [Errno 11001] getaddrinfo failed
[2020-01-14 18:36:28][log.py][line:58][INFO] 
[2020-01-14 18:36:28][log.py][line:68][ERROR] 产生错误于：【dv95557117@126.com】发送失败
[2020-01-14 18:36:28][log.py][line:68][ERROR] [Errno 11001] getaddrinfo failed
[2020-01-14 18:36:28][log.py][line:58][INFO] 
[2020-01-14 18:36:29][log.py][line:68][ERROR] 产生错误于：【cnk568@163.com】发送失败
[2020-01-14 18:36:29][log.py][line:68][ERROR] [Errno 11001] getaddrinfo failed
[2020-01-14 18:36:29][log.py][line:58][INFO] 
[2020-01-14 18:36:30][log.py][line:68][ERROR] 产生错误于：【gmw77r@163.com】发送失败
[2020-01-14 18:36:30][log.py][line:68][ERROR] [Errno 11001] getaddrinfo failed
[2020-01-14 18:36:30][log.py][line:58][INFO] 
[2020-01-14 18:36:31][log.py][line:68][ERROR] 产生错误于：【ss13126325@sina.com】发送失败
[2020-01-14 18:36:31][log.py][line:68][ERROR] [Errno 11001] getaddrinfo failed
[2020-01-14 18:36:31][log.py][line:58][INFO] 
[2020-01-14 18:36:32][log.py][line:68][ERROR] 产生错误于：【lzm460@163.com】发送失败
[2020-01-14 18:36:32][log.py][line:68][ERROR] [Errno 11001] getaddrinfo failed
[2020-01-14 18:36:32][log.py][line:58][INFO] 
[2020-01-14 18:36:39][log.py][line:68][ERROR] 产生错误于：【ngz934@163.com】发送失败
[2020-01-14 18:36:39][log.py][line:68][ERROR] [Errno 11001] getaddrinfo failed
[2020-01-14 18:36:39][log.py][line:58][INFO] 
[2020-01-14 18:36:40][log.py][line:68][ERROR] 产生错误于：【w8i46z@163.com】发送失败
[2020-01-14 18:36:40][log.py][line:68][ERROR] [Errno 11001] getaddrinfo failed
[2020-01-14 18:36:40][log.py][line:58][INFO] 
[2020-01-14 18:36:52][log.py][line:68][ERROR] 产生错误于：【dquan242sl@126.com】发送失败
[2020-01-14 18:36:52][log.py][line:68][ERROR] [Errno 11001] getaddrinfo failed
[2020-01-14 18:36:52][log.py][line:58][INFO] 
[2020-01-14 18:36:53][log.py][line:68][ERROR] 产生错误于：【vggem2066rd@126.com】发送失败
[2020-01-14 18:36:53][log.py][line:68][ERROR] [Errno 11001] getaddrinfo failed
[2020-01-14 18:36:53][log.py][line:58][INFO] 
[2020-01-14 18:36:54][log.py][line:68][ERROR] 产生错误于：【bismw8916cu@126.com】发送失败
[2020-01-14 18:36:54][log.py][line:68][ERROR] [Errno 11001] getaddrinfo failed
[2020-01-14 18:36:54][log.py][line:58][INFO] 
[2020-01-14 18:36:55][log.py][line:68][ERROR] 产生错误于：【 n8m4yc@163.com】发送失败
[2020-01-14 18:36:55][log.py][line:68][ERROR] [Errno 11001] getaddrinfo failed
[2020-01-14 18:36:55][log.py][line:58][INFO] 
[2020-01-14 18:36:56][log.py][line:68][ERROR] 产生错误于：【bb652f@163.com】发送失败
[2020-01-14 18:36:56][log.py][line:68][ERROR] [Errno 11001] getaddrinfo failed
[2020-01-14 18:36:56][log.py][line:58][INFO] 
[2020-01-14 18:37:04][log.py][line:68][ERROR] 产生错误于：【mmtby7664qa@126.com】发送失败
[2020-01-14 18:37:04][log.py][line:68][ERROR] [Errno 11001] getaddrinfo failed
[2020-01-14 18:37:04][log.py][line:58][INFO] 
[2020-01-14 18:37:05][log.py][line:68][ERROR] 产生错误于：【y77xz3@163.com】发送失败
[2020-01-14 18:37:05][log.py][line:68][ERROR] [Errno 11001] getaddrinfo failed
[2020-01-14 18:37:05][log.py][line:58][INFO] 
[2020-01-14 18:37:06][log.py][line:68][ERROR] 产生错误于：【ss13126325@sina.com】发送失败
[2020-01-14 18:37:06][log.py][line:68][ERROR] [Errno 11001] getaddrinfo failed
[2020-01-14 18:37:06][log.py][line:58][INFO] 
[2020-01-14 18:37:07][log.py][line:68][ERROR] 产生错误于：【 v9m55j@163.com】发送失败
[2020-01-14 18:37:07][log.py][line:68][ERROR] [Errno 11001] getaddrinfo failed
[2020-01-14 18:37:07][log.py][line:58][INFO] 
[2020-01-14 18:37:18][log.py][line:68][ERROR] 产生错误于：【bb652f@163.com】发送失败
[2020-01-14 18:37:18][log.py][line:68][ERROR] [Errno 11001] getaddrinfo failed
[2020-01-14 18:37:18][log.py][line:58][INFO] 
[2020-01-14 18:37:19][log.py][line:68][ERROR] 产生错误于：【k610px@163.com】发送失败
[2020-01-14 18:37:19][log.py][line:68][ERROR] [Errno 11001] getaddrinfo failed
[2020-01-14 18:37:19][log.py][line:58][INFO] 
[2020-01-14 18:37:20][log.py][line:68][ERROR] 产生错误于：【aenbx0418ck@126.com】发送失败
[2020-01-14 18:37:20][log.py][line:68][ERROR] [Errno 11001] getaddrinfo failed
[2020-01-14 18:37:20][log.py][line:58][INFO] 
[2020-01-14 18:37:30][log.py][line:68][ERROR] 产生错误于：【ss13126325@sina.com】发送失败
[2020-01-14 18:37:30][log.py][line:68][ERROR] [Errno 11001] getaddrinfo failed
[2020-01-14 18:37:30][log.py][line:58][INFO] 
[2020-01-14 18:37:42][log.py][line:68][ERROR] 产生错误于：【xuoyw4788ok@126.com】发送失败
[2020-01-14 18:37:42][log.py][line:68][ERROR] [Errno 11001] getaddrinfo failed
[2020-01-14 18:37:42][log.py][line:58][INFO] 
[2020-01-14 18:37:43][log.py][line:68][ERROR] 产生错误于：【b142qs@163.com】发送失败
[2020-01-14 18:37:43][log.py][line:68][ERROR] [Errno 11001] getaddrinfo failed
[2020-01-14 18:37:43][log.py][line:58][INFO] 
[2020-01-14 18:37:43][log.py][line:58][INFO] 邮件总数量【397】
[2020-01-14 18:37:43][log.py][line:58][INFO] 总计发送邮件数量【78】
[2020-01-14 18:37:43][log.py][line:58][INFO] 总计发送错误数量【319】
[2020-01-14 18:37:43][log.py][line:58][INFO] 成功邮箱账号集合：ss13126325@sina.com,uu24680644@126.com,ezjsh7913yb@126.com,k737jk@163.com,bqasq3282ug@126.com,ciema0687mt@126.com,nah5ae@163.com,o6n553@163.com,ucr2ue@163.com,ss13126325@sina.com,ss13126325@sina.com,ss13126325@sina.com,ss13126325@sina.com,mwk2h8@163.com,ofaxp0781kr@126.com,fmb72b@163.com,jmd597@163.com,ss13126325@sina.com,wcqta7018af@126.com,ss13126325@sina.com,ss13126325@sina.com,smbnh6865dm@126.com,kff22c@163.com,ss13126325@sina.com,ss13126325@sina.com,ryoqf0834bs@126.com,sk248028226@126.com,u4s658@163.com,ibqhn0074ck@126.com,bl21q6@163.com,urt6ca@163.com,qvgxd8220mk@126.com,ss13126325@sina.com,ss13126325@sina.com,ss13126325@sina.com,ss13126325@sina.com,ss13126325@sina.com,gcv7rk@163.com,vhw6n9@163.com,ss13126325@sina.com,ypovw7381jq@126.com,ss13126325@sina.com,b8y5yb@163.com,ss13126325@sina.com,fpgic3160mg@126.com,qvgxd8220mk@126.com,pmncd4350xu@126.com,ss13126325@sina.com,e5l8g7@163.com,icvma2101ry@126.com,oprul919zy@126.com,e4m6s2@163.com,ngm67a@163.com,ss13126325@sina.com,bgk90z@163.com,ubnpx7683xu@126.com,u1v00h@163.com,ddonv7986lj@126.com,luwwd0361rs@126.com,fdxdi580so@126.com,ss13126325@sina.com,dtf1gb@163.com,gncjm0521ou@126.com,okrbh0857wq@126.com,ss13126325@sina.com,fdn975333@126.com,ss13126325@sina.com,ss13126325@sina.com,hljeq7441qu@126.com,aqjyn4615jq@126.com,ibqhn0074ck@126.com,ybk8zf@163.com,e2e8xt@163.com,ss13126325@sina.com,ss13126325@sina.com,bwg6qg@163.com,qkclo2932ex@126.com,xkq9kr@163.com
[2020-01-14 18:37:43][log.py][line:58][INFO] 脚本结束------------------------------------------------------------------
[2020-01-14 18:37:43][log.py][line:58][INFO] 
